Workbook

Sheet 审阅导航
A2: 汽车访谈题库：2C与2B独立结构
A4: 2C按生活背景与本人经历展开；2B先交代受访者机构与市场背景，再讨论客户画像和成交。
A5: 2C仅保留消费者本人；商务/组织采购者移至2B独立模块，并按实际采购与使用经历触发。
A6: 2B按经销商、媒体、主机厂专家、商务/组织采购者分角色。每题只对具有相应职责和证据的对象出现。
A7: 2C共143个题卡；2B合并后共51个题卡。来源映射保留，不把合并视为删失原始资料。
A8: 2C明确设置“购车考虑因素”和“补贴与政策影响”；产品概念、价格、卖点等题目均增加材料触发条件。
A9: 先看两套目录，再分别审阅；黄色列可填确认状态及意见。原题、原追问和历史材料保留在末尾来源表。
A10: 原追问是来源审阅层，混合角色原文保留；执行时应按本表2C/2B口径调整，不直接全量拼接。
A11: 国家政策、历史价格及技术参数仍待项目核验；本次未修改网站。
A13: 顺序 | B13: 独立模块 | C13: 条目数 | D13: 已同意 | E13: 需修改 | F13: 待审阅 | G13: 模块任务 | H13: 执行说明
A14: C0 | B14: 2C-00 执行话术 | C14: =COUNTA('2C-00 执行话术'!A6:A8) -> 3 | D14: =COUNTIFS('2C-00 执行话术'!H6:H8,"同意") -> 3 | E14: =COUNTIFS('2C-00 执行话术'!H6:H8,"需修改") -> 0 | F14: =COUNTIFS('2C-00 执行话术'!H6:H8,"待审阅") -> 0 | G14: 开场、观察许可与收尾话术 | H14: 执行工具：开场置前，收尾置后
A15: C1 | B15: 2C-01 生活与车辆背景 | C15: =COUNTA('2C-01 生活与车辆背景'!A6:A19) -> 14 | D15: =COUNTIFS('2C-01 生活与车辆背景'!H6:H19,"同意") -> 13 | E15: =COUNTIFS('2C-01 生活与车辆背景'!H6:H19,"需修改") -> 0 | F15: =COUNTIFS('2C-01 生活与车辆背景'!H6:H19,"待审阅") -> 0 | G15: 开场建立消费者本人生活与车辆背景 | H15: 模块内按项目目标选题，不要求全部问完
A16: C2 | B16: 2C-02 场景与体验 | C16: =COUNTA('2C-02 场景与体验'!A6:A41) -> 36 | D16: =COUNTIFS('2C-02 场景与体验'!H6:H41,"同意") -> 34 | E16: =COUNTIFS('2C-02 场景与体验'!H6:H41,"需修改") -> 0 | F16: =COUNTIFS('2C-02 场景与体验'!H6:H41,"待审阅") -> 0 | G16: 还原真实场景、体验、痛点及本地条件 | H16: 模块内按项目目标选题，不要求全部问完
A17: C3 | B17: 2C-03 购买旅程与考虑因素 | C17: =COUNTA('2C-03 购买旅程与考虑因素'!A6:A28) -> 23 | D17: =COUNTIFS('2C-03 购买旅程与考虑因素'!H6:H28,"同意") -> 19 | E17: =COUNTIFS('2C-03 购买旅程与考虑因素'!H6:H28,"需修改") -> 0 | F17: =COUNTIFS('2C-03 购买旅程与考虑因素'!H6:H28,"待审阅") -> 0 | G17: 购车旅程、考虑因素、支付、补贴及政策影响 | H17: 模块内按项目目标选题，不要求全部问完
A18: C4 | B18: 2C-04 动力与补能 | C18: =COUNTA('2C-04 动力与补能'!A6:A25) -> 20 | D18: =COUNTIFS('2C-04 动力与补能'!H6:H25,"同意") -> 15 | E18: =COUNTIFS('2C-04 动力与补能'!H6:H25,"需修改") -> 0 | F18: =COUNTIFS('2C-04 动力与补能'!H6:H25,"待审阅") -> 0 | G18: 结合实际任务讨论动力与补能 | H18: 模块内按项目目标选题，不要求全部问完
A19: C5 | B19: 2C-05 产品与配置 | C19: =COUNTA('2C-05 产品与配置'!A6:A37) -> 32 | D19: =COUNTIFS('2C-05 产品与配置'!H6:H37,"同意") -> 25 | E19: =COUNTIFS('2C-05 产品与配置'!H6:H37,"需修改") -> 0 | F19: =COUNTIFS('2C-05 产品与配置'!H6:H37,"待审阅") -> 0 | G19: 明确材料后评价产品和配置 | H19: 模块内按项目目标选题，不要求全部问完
A20: C6 | B20: 2C-06 品牌与购买条件 | C20: =COUNTA('2C-06 品牌与购买条件'!A6:A20) -> 15 | D20: =COUNTIFS('2C-06 品牌与购买条件'!H6:H20,"同意") -> 15 | E20: =COUNTIFS('2C-06 品牌与购买条件'!H6:H20,"需修改") -> 0 | F20: =COUNTIFS('2C-06 品牌与购买条件'!H6:H20,"待审阅") -> 0 | G20: 品牌理解、价格取舍与购买条件 | H20: 模块内按项目目标选题，不要求全部问完
A21: B0 | B21: 2B-00 执行话术 | C21: =COUNTA('2B-00 执行话术'!A6:A7) -> 2 | D21: =COUNTIFS('2B-00 执行话术'!H6:H7,"同意") -> 2 | E21: =COUNTIFS('2B-00 执行话术'!H6:H7,"需修改") -> 0 | F21: =COUNTIFS('2B-00 执行话术'!H6:H7,"待审阅") -> 0 | G21: 开场参与说明与最后核对 | H21: 执行工具：开场置前，收尾置后
A22: B1 | B22: 2B-01 受访者与机构背景 | C22: =COUNTA('2B-01 受访者与机构背景'!A6:A7) -> 2 | D22: =COUNTIFS('2B-01 受访者与机构背景'!H6:H7,"同意") -> 2 | E22: =COUNTIFS('2B-01 受访者与机构背景'!H6:H7,"需修改") -> 0 | F22: =COUNTIFS('2B-01 受访者与机构背景'!H6:H7,"待审阅") -> 0 | G22: 确认受访者职责与机构范围 | H22: 受访者本人/机构背景；不是客户画像
A23: B2 | B23: 2B-02 品牌市场与政策 | C23: =COUNTA('2B-02 品牌市场与政策'!A6:A9) -> 4 | D23: =COUNTIFS('2B-02 品牌市场与政策'!H6:H9,"同意") -> 4 | E23: =COUNTIFS('2B-02 品牌市场与政策'!H6:H9,"需修改") -> 0 | F23: =COUNTIFS('2B-02 品牌市场与政策'!H6:H9,"待审阅") -> 0 | G23: 品牌、市场、销量、补贴与政策背景 | H23: 模块内按项目目标选题，不要求全部问完
A24: B3 | B24: 2B-03 客户画像与用途 | C24: =COUNTA('2B-03 客户画像与用途'!A6:A9) -> 4 | D24: =COUNTIFS('2B-03 客户画像与用途'!H6:H9,"同意") -> 2 | E24: =COUNTIFS('2B-03 客户画像与用途'!H6:H9,"需修改") -> 2 | F24: =COUNTIFS('2B-03 客户画像与用途'!H6:H9,"待审阅") -> 0 | G24: 客户画像、车辆关系与典型用途 | H24: 模块内按项目目标选题，不要求全部问完
A25: B4 | B25: 2B-04 成交与流失 | C25: =COUNTA('2B-04 成交与流失'!A6:A11) -> 6 | D25: =COUNTIFS('2B-04 成交与流失'!H6:H11,"同意") -> 6 | E25: =COUNTIFS('2B-04 成交与流失'!H6:H11,"需修改") -> 0 | F25: =COUNTIFS('2B-04 成交与流失'!H6:H11,"待审阅") -> 0 | G25: 购买触发、考虑因素、成交及流失 | H25: 模块内按项目目标选题，不要求全部问完
A26: B5 | B26: 2B-05 产品需求与方案 | C26: =COUNTA('2B-05 产品需求与方案'!A6:A16) -> 11 | D26: =COUNTIFS('2B-05 产品需求与方案'!H6:H16,"同意") -> 11 | E26: =COUNTIFS('2B-05 产品需求与方案'!H6:H16,"需修改") -> 0 | F26: =COUNTIFS('2B-05 产品需求与方案'!H6:H16,"待审阅") -> 0 | G26: 从客户反馈和专业证据评价产品 | H26: 模块内按项目目标选题，不要求全部问完
A27: B6 | B27: 2B-06 价格版型与盈利 | C27: =COUNTA('2B-06 价格版型与盈利'!A6:A9) -> 4 | D27: =COUNTIFS('2B-06 价格版型与盈利'!H6:H9,"同意") -> 4 | E27: =COUNTIFS('2B-06 价格版型与盈利'!H6:H9,"需修改") -> 0 | F27: =COUNTIFS('2B-06 价格版型与盈利'!H6:H9,"待审阅") -> 0 | G27: 预算、价格、金融和经销商盈利 | H27: 模块内按项目目标选题，不要求全部问完
A28: B7 | B28: 2B-07 渠道营销与服务 | C28: =COUNTA('2B-07 渠道营销与服务'!A6:A9) -> 4 | D28: =COUNTIFS('2B-07 渠道营销与服务'!H6:H9,"同意") -> 4 | E28: =COUNTIFS('2B-07 渠道营销与服务'!H6:H9,"需修改") -> 0 | F28: =COUNTIFS('2B-07 渠道营销与服务'!H6:H9,"待审阅") -> 0 | G28: 获客、传播、渠道与售后服务 | H28: 模块内按项目目标选题，不要求全部问完
A29: B8 | B29: 2B-08 品牌机会与策略 | C29: =COUNTA('2B-08 品牌机会与策略'!A6:A10) -> 5 | D29: =COUNTIFS('2B-08 品牌机会与策略'!H6:H10,"同意") -> 5 | E29: =COUNTIFS('2B-08 品牌机会与策略'!H6:H10,"需修改") -> 0 | F29: =COUNTIFS('2B-08 品牌机会与策略'!H6:H10,"待审阅") -> 0 | G29: 品牌形象、中国品牌与市场进入 | H29: 模块内按项目目标选题，不要求全部问完
A30: B9 | B30: 2B-09 商务与组织采购 | C30: =COUNTA('2B-09 商务与组织采购'!A6:A14) -> 9 | D30: =COUNTIFS('2B-09 商务与组织采购'!H6:H14,"同意") -> 9 | E30: =COUNTIFS('2B-09 商务与组织采购'!H6:H14,"需修改") -> 0 | F30: =COUNTIFS('2B-09 商务与组织采购'!H6:H14,"待审阅") -> 0 | G30: 商务与组织车辆的真实采购和使用 | H30: 模块内按项目目标选题，不要求全部问完
B32: 2C题卡合计 | C32: =SUM(C14:C20) -> 143 | D32: =SUM(D14:D20) -> 124 | E32: =SUM(E14:E20) -> 0 | F32: =SUM(F14:F20) -> 0
B33: 2B题卡合计 | C33: =SUM(C21:C30) -> 51 | D33: =SUM(D21:D30) -> 49 | E33: =SUM(E21:E30) -> 2 | F33: =SUM(F21:F30) -> 0
A36: FGD与IHV的执行差异
A37: FGD可按2C目录推进，先个人回答再讨论；IHV先背景与购买旅程，再沿真实看车动线串联场景、空间和补能任务。
A39: 2B按角色触发：经销商答客户与订单，媒体答传播和公开观察，主机厂专家答职责范围内的市场/产品证据，商务与组织采购者答本组织经历。

Sheet 2C-00 执行话术
A2: 2C-00 执行话术
A3: 3张题卡。2C：消费者本人及家庭的真实经历。黄色列供你填写；核心信息已回答就不重复问。
A5: 题卡编号 | B5: 子模块与适用方法 | C5: 研究目的与边界 | D5: 主问：按对象选用 | E5: 核心追问：覆盖信息 | F5: 触发条件与观察任务 | G5: 归并调整与来源 | H5: 确认状态 | I5: 你的修改意见
A6: Q-E0-01 | B6: C0 执行话术 核心信息 FGD：可用 IHV：可用 | C6: 明确参与许可、记录口径与结束核对，执行环节不计研究模块。 | D6: 车主：今天我们想了解您的真实出行与选车经历，没有标准答案。您可以不回答任何不愿谈的问题；开始前是否愿意参与？ 意向者：今天我们想了解您的真实出行与选车经历，没有标准答案。您可以不回答任何不愿谈的问题；开始前是否愿意参与？ | E6: 1. 说明研究目的、预计时长、资料用途与保密安排 2. 如需录音、拍照或观察，分别征求许可；拒绝不影响继续交流 3. 记录日期、地点、访问员、受访者代号与必要的样本信息 | F6: 按研究目的选用；有实际经历先谈经历，设想单独记录。 原追问4条：在“原追问审阅”按题卡编号筛选；详情保留在该表，不能把全部追问逐项念出。 | G6: 2C用户本人提纲：按生活背景—经历—选择—方案的顺序呈现。保留研究任务，按对象区分问法；同义主问合并，细节保留为按条件追问。 原编号题：5条；在“原题映射”按本题编号检索。 | H6: 同意
A7: Q-E0-02 | B7: C0 执行话术 按需选择 FGD：不适用 IHV：可用 | C7: 明确参与许可、记录口径与结束核对，执行环节不计研究模块。 | D7: 车主：在您愿意的范围内，能否带我们看看与日常出行和物品收纳有关的空间？ 意向者：在您愿意的范围内，能否带我们看看与日常出行和物品收纳有关的空间？ | E7: 1. 不进入不愿展示的区域 2. 只记录研究相关观察 3. 观察与解释分开 | F7: 仅IHV现场，征得观察许可。 原追问1条：在“原追问审阅”按题卡编号筛选；详情保留在该表，不能把全部追问逐项念出。 | G7: 2C用户本人提纲：按生活背景—经历—选择—方案的顺序呈现。保留研究任务，按对象区分问法；同义主问合并，细节保留为按条件追问。 原编号题：1条；在“原题映射”按本题编号检索。 | H7: 同意
A8: Q-E0-03 | B8: C0 执行话术 核心信息 FGD：可用 IHV：可用 | C8: 明确参与许可、记录口径与结束核对，执行环节不计研究模块。 | D8: 车主：还有什么重要情况没有谈到？如果只留下三条建议，您最希望我们记住什么？ 意向者：还有什么重要情况没有谈到？如果只留下三条建议，您最希望我们记住什么？ | E8: 1. 回到研究目的 2. 区分优先级 3. 核对是否误解 | F8: 按研究目的选用；有实际经历先谈经历，设想单独记录。 原追问1条：在“原追问审阅”按题卡编号筛选；详情保留在该表，不能把全部追问逐项念出。 | G8: 2C用户本人提纲：按生活背景—经历—选择—方案的顺序呈现。保留研究任务，按对象区分问法；同义主问合并，细节保留为按条件追问。 原编号题：4条；在“原题映射”按本题编号检索。 | H8: 同意

Sheet 2C-01 生活与车辆背景
A2: 2C-01 生活与车辆背景
A3: 14张题卡。2C：消费者本人及家庭的真实经历。黄色列供你填写；核心信息已回答就不重复问。
A5: 题卡编号 | B5: 子模块与适用方法 | C5: 研究目的与边界 | D5: 主问：按对象选用 | E5: 核心追问：覆盖信息 | F5: 触发条件与观察任务 | G5: 归并调整与来源 | H5: 确认状态 | I5: 你的修改意见
A6: Q-M1.1-01 | B6: C1 家庭／组织与生活背景 核心信息 FGD：可用 IHV：可用 | C6: 建立消费者本人、家庭与日常生活背景，作为后续用车场景的开场信息。 | D6: 车主：请简单介绍您的日常工作、共同生活的人，以及目前的生活安排。 意向者：请简单介绍您的日常工作、共同生活的人，以及目前的生活安排。 | E6: 1. 家庭成员年龄段与照护责任 2. 只记录与用车有关的信息，不要求透露不愿提供的隐私 | F6: 按研究目的选用；有实际经历先谈经历，设想单独记录。 原追问3条：在“原追问审阅”按题卡编号筛选；详情保留在该表，不能把全部追问逐项念出。 | G6: 按审阅意见删除商务/组织版本，只保留消费者本人开场。 原编号题：9条；在“原题映射”按本题编号检索。 | H6: 已按意见修改 | I6: 商务/组织是2B
A7: Q-M1.1-02 | B7: C1 家庭／组织与生活背景 按需选择 FGD：可用 IHV：可用 | C7: 开场建立生活与用车背景。识别生活阶段、照护与工作背景，为目标人群和出行需求分组。 不把背景描述单独解释为市场人群占比。 | D7: 车主：平时哪些兴趣或活动最占用您的时间？最近一次是怎么安排出行的？ 意向者：平时哪些兴趣或活动最占用您的时间？最近一次是怎么安排出行的？ | E7: 1. 带了什么人和物品 2. 是否需要接送、装载或远行 3. 哪些活动想参加却受出行条件限制 | F7: 按研究目的选用；有实际经历先谈经历，设想单独记录。 原追问1条：在“原追问审阅”按题卡编号筛选；详情保留在该表，不能把全部追问逐项念出。 | G7: 2C用户本人提纲：按生活背景—经历—选择—方案的顺序呈现。保留研究任务，按对象区分问法；同义主问合并，细节保留为按条件追问。 原编号题：4条；在“原题映射”按本题编号检索。 | H7: 同意
A8: Q-M1.1-04 | B8: C1 家庭／组织与生活背景 按需选择 FGD：可用 IHV：可用 | C8: 开场建立生活与用车背景。识别生活阶段、照护与工作背景，为目标人群和出行需求分组。 不把背景描述单独解释为市场人群占比。 | D8: 车主：未来三到五年，您预计生活或工作会有哪些变化，可能改变出行需要？ 意向者：未来三到五年，您预计生活或工作会有哪些变化，可能改变出行需要？ | E8: 1. 新增照护或工作责任 2. 居住变化 3. 哪些已经确定，哪些只是设想 | F8: 按研究目的选用；有实际经历先谈经历，设想单独记录。 原追问0条：在“原追问审阅”按题卡编号筛选；详情保留在该表，不能把全部追问逐项念出。 | G8: 2C用户本人提纲：按生活背景—经历—选择—方案的顺序呈现。保留研究任务，按对象区分问法；同义主问合并，细节保留为按条件追问。 原编号题：1条；在“原题映射”按本题编号检索。 | H8: 同意
A9: Q-M1.1-05 | B9: C1 家庭／组织与生活背景 按需选择 FGD：可用 IHV：可用 | C9: 开场建立生活与用车背景。识别生活阶段、照护与工作背景，为目标人群和出行需求分组。 不把背景描述单独解释为市场人群占比。 | D9: 车主：请介绍您在组织中的职责，以及这次公务或营运用车涉及的业务。 意向者：请介绍您在组织中的职责，以及这次公务或营运用车涉及的业务。 | E9: 1. 组织规模和服务对象 2. 车辆承担的工作 3. 本人参与使用、采购还是审批 | F9: 实际涉及公务、营运或机构采购；不因价格或级别推定商务用途。 原追问1条：在“原追问审阅”按题卡编号筛选；详情保留在该表，不能把全部追问逐项念出。 | G9: 2C用户本人提纲：按生活背景—经历—选择—方案的顺序呈现。保留研究任务，按对象区分问法；同义主问合并，细节保留为按条件追问。 原编号题：1条；在“原题映射”按本题编号检索。 | H9: 同意
A10: Q-M1.2-01 | B10: C1 车辆组合与分工 核心信息 FGD：可用 IHV：可用 | C10: 开场建立生活与用车背景。识别车辆组合与替代关系，明确新车承担的任务。 不把背景描述单独解释为市场人群占比。 | D10: 车主：目前家庭或组织有哪些车辆？各自负责什么出行任务？ 意向者：目前家庭有哪些车辆或交通方式？未来新增车辆希望补足什么任务？ | E10: 1. 车型、动力、购买时间 2. 没有车时使用什么交通方式 3. 是否有重复或无法覆盖的任务 | F10: 按研究目的选用；有实际经历先谈经历，设想单独记录。 原追问5条：在“原追问审阅”按题卡编号筛选；详情保留在该表，不能把全部追问逐项念出。 | G10: 2C用户本人提纲：按生活背景—经历—选择—方案的顺序呈现。保留研究任务，按对象区分问法；同义主问合并，细节保留为按条件追问。 原编号题：5条；在“原题映射”按本题编号检索。 | H10: 同意
A11: Q-M1.2-02 | B11: C1 车辆组合与分工 按需选择 FGD：可用 IHV：可用 | C11: 开场建立生活与用车背景。识别车辆组合与替代关系，明确新车承担的任务。 不把背景描述单独解释为市场人群占比。 | D11: 车主：回顾之前使用过的车辆，为什么发生了这些变化？ 意向者：过去家庭或您自己使用的车辆、交通方式发生过哪些变化？为什么？ | E11: 1. 首购、增购还是替换 2. 保留或淘汰原因 3. 不是追问所有车辆履历 | F11: 按研究目的选用；有实际经历先谈经历，设想单独记录。 原追问3条：在“原追问审阅”按题卡编号筛选；详情保留在该表，不能把全部追问逐项念出。 | G11: 2C用户本人提纲：按生活背景—经历—选择—方案的顺序呈现。保留研究任务，按对象区分问法；同义主问合并，细节保留为按条件追问。 原编号题：3条；在“原题映射”按本题编号检索。 | H11: 同意
A12: Q-M1.2-03 | B12: C1 车辆组合与分工 按需选择 FGD：可用 IHV：可用 | C12: 开场建立生活与用车背景。识别车辆组合与替代关系，明确新车承担的任务。 不把背景描述单独解释为市场人群占比。 | D12: 车主：如果增加或更换一辆车，现有车辆和其他交通方式会如何分工？ 意向者：如果增加或更换一辆车，现有车辆和其他交通方式会如何分工？ | E12: 1. 哪些任务会转移 2. 是否减少其他车辆 3. 工作与私人用途如何协调 | F12: 按研究目的选用；有实际经历先谈经历，设想单独记录。 原追问1条：在“原追问审阅”按题卡编号筛选；详情保留在该表，不能把全部追问逐项念出。 | G12: 2C用户本人提纲：按生活背景—经历—选择—方案的顺序呈现。保留研究任务，按对象区分问法；同义主问合并，细节保留为按条件追问。 原编号题：1条；在“原题映射”按本题编号检索。 | H12: 同意
A13: Q-M1.3-01 | B13: C1 使用者、乘员与决策角色 核心信息 FGD：可用 IHV：可用 | C13: 开场建立生活与用车背景。区分驾驶、乘坐、付款和决策角色，支持座位布局与决策沟通。 不把背景描述单独解释为市场人群占比。 | D13: 车主：平时谁负责驾驶，谁主要乘坐？不同出行任务会换人吗？ 意向者：平时谁负责驾驶，谁主要乘坐？不同出行任务会换人吗？ | E13: 1. 驾驶者与主要乘员是否同一人 2. 家人、同事、专职司机的分工 3. 谁很少开但经常坐 | F13: 按研究目的选用；有实际经历先谈经历，设想单独记录。 原追问5条：在“原追问审阅”按题卡编号筛选；详情保留在该表，不能把全部追问逐项念出。 | G13: 2C用户本人提纲：按生活背景—经历—选择—方案的顺序呈现。保留研究任务，按对象区分问法；同义主问合并，细节保留为按条件追问。 原编号题：7条；在“原题映射”按本题编号检索。 | H13: 同意
A14: Q-M1.3-02 | B14: C1 使用者、乘员与决策角色 按需选择 FGD：可用 IHV：可用 | C14: 开场建立生活与用车背景。区分驾驶、乘坐、付款和决策角色，支持座位布局与决策沟通。 不把背景描述单独解释为市场人群占比。 | D14: 车主：通常有哪些人一起出行，他们如何安排座位？ 意向者：通常有哪些人一起出行，他们如何安排座位？ | E14: 1. 人数、频次、儿童座椅或行动便利需求 2. 谁决定座位 3. 满员与日常的差别 | F14: 按研究目的选用；有实际经历先谈经历，设想单独记录。 原追问4条：在“原追问审阅”按题卡编号筛选；详情保留在该表，不能把全部追问逐项念出。 | G14: 2C用户本人提纲：按生活背景—经历—选择—方案的顺序呈现。保留研究任务，按对象区分问法；同义主问合并，细节保留为按条件追问。 原编号题：7条；在“原题映射”按本题编号检索。 | H14: 同意
A15: Q-M1.3-03 | B15: C1 使用者、乘员与决策角色 按需选择 FGD：可用 IHV：可用 | C15: 开场建立生活与用车背景。区分驾驶、乘坐、付款和决策角色，支持座位布局与决策沟通。 不把背景描述单独解释为市场人群占比。 | D15: 车主：选车、付款和最终决定分别由谁负责？ 意向者：选车、付款和最终决定分别由谁负责？ | E15: 1. 信息搜集者、影响者、否决者 2. 女性或长辈影响力按实际角色问，不预设差异 | F15: 按研究目的选用；有实际经历先谈经历，设想单独记录。 原追问7条：在“原追问审阅”按题卡编号筛选；详情保留在该表，不能把全部追问逐项念出。 | G15: 2C用户本人提纲：按生活背景—经历—选择—方案的顺序呈现。保留研究任务，按对象区分问法；同义主问合并，细节保留为按条件追问。 原编号题：9条；在“原题映射”按本题编号检索。 | H15: 同意
A16: Q-M1.3-04 | B16: C1 使用者、乘员与决策角色 按需选择 FGD：可用 IHV：可用 | C16: 开场建立生活与用车背景。区分驾驶、乘坐、付款和决策角色，支持座位布局与决策沟通。 不把背景描述单独解释为市场人群占比。 | D16: 车主：请还原一次车辆采购的审批过程。 意向者：请还原一次车辆采购的审批过程。 | E16: 1. 需求提出、预算、试用、审批、签单 2. 司机和乘员意见如何进入决策 3. 采购数量及节奏 | F16: 实际涉及公务、营运或机构采购；不因价格或级别推定商务用途。 原追问3条：在“原追问审阅”按题卡编号筛选；详情保留在该表，不能把全部追问逐项念出。 | G16: 2C用户本人提纲：按生活背景—经历—选择—方案的顺序呈现。保留研究任务，按对象区分问法；同义主问合并，细节保留为按条件追问。 原编号题：1条；在“原题映射”按本题编号检索。 | H16: 同意 | I16: 这个是采购吧，商务
A17: Q-M1.4-01 | B17: C1 品类意义与理想形象 按需选择 FGD：可用 IHV：可用 | C17: 开场建立生活与用车背景。理解品类意义、理想形象及社会评价，为定位提供依据。 不把背景描述单独解释为市场人群占比。 | D17: 车主：在您看来，这类车适合什么人、用来做什么？ 意向者：在您看来，这类车适合什么人、用来做什么？ | E17: 1. 与其他车身类别的区别 2. 功能、身份、社交含义 3. 先自由描述，不给褒贬标签 | F17: 按研究目的选用；有实际经历先谈经历，设想单独记录。 原追问5条：在“原追问审阅”按题卡编号筛选；详情保留在该表，不能把全部追问逐项念出。 | G17: 2C用户本人提纲：按生活背景—经历—选择—方案的顺序呈现。保留研究任务，按对象区分问法；同义主问合并，细节保留为按条件追问。 原编号题：3条；在“原题映射”按本题编号检索。 | H17: 同意
A18: Q-M1.4-02 | B18: C1 品类意义与理想形象 按需选择 FGD：可用 IHV：可用 | C18: 开场建立生活与用车背景。理解品类意义、理想形象及社会评价，为定位提供依据。 不把背景描述单独解释为市场人群占比。 | D18: 车主：如果用三个词描述适合您的理想车辆，您会选什么？ 意向者：如果用三个词描述适合您的理想车辆，您会选什么？ | E18: 1. 每个词对应一个真实场景 2. 只能保留一个时如何选 3. 家用与商务标准有何不同 | F18: 按研究目的选用；有实际经历先谈经历，设想单独记录。 原追问4条：在“原追问审阅”按题卡编号筛选；详情保留在该表，不能把全部追问逐项念出。 | G18: 2C用户本人提纲：按生活背景—经历—选择—方案的顺序呈现。保留研究任务，按对象区分问法；同义主问合并，细节保留为按条件追问。 原编号题：4条；在“原题映射”按本题编号检索。 | H18: 同意
A19: Q-M1.4-03 | B19: C1 品类意义与理想形象 按需选择 FGD：可用 IHV：可用 | C19: 开场建立生活与用车背景。理解品类意义、理想形象及社会评价，为定位提供依据。 不把背景描述单独解释为市场人群占比。 | D19: 车主：身边的人怎样看待这类车？哪些看法实际影响过您？ 意向者：身边的人怎样看待这类车？哪些看法实际影响过您？ | E19: 1. 亲身接触与听说区分 2. 圈层认可或顾虑 3. 是否改变候选或使用方式 | F19: 按研究目的选用；有实际经历先谈经历，设想单独记录。 原追问1条：在“原追问审阅”按题卡编号筛选；详情保留在该表，不能把全部追问逐项念出。 | G19: 2C用户本人提纲：按生活背景—经历—选择—方案的顺序呈现。保留研究任务，按对象区分问法；同义主问合并，细节保留为按条件追问。 原编号题：5条；在“原题映射”按本题编号检索。 | H19: 同意

Sheet 2C-02 场景与体验
A2: 2C-02 场景与体验
A3: 36张题卡。2C：消费者本人及家庭的真实经历。黄色列供你填写；核心信息已回答就不重复问。
A5: 题卡编号 | B5: 子模块与适用方法 | C5: 研究目的与边界 | D5: 主问：按对象选用 | E5: 核心追问：覆盖信息 | F5: 触发条件与观察任务 | G5: 归并调整与来源 | H5: 确认状态 | I5: 你的修改意见
A6: Q-M2.1-01 | B6: C2 高频使用场景 核心信息 FGD：可用 IHV：可用 | C6: 还原出行任务组合，为样本细分、车辆角色和场景覆盖提供依据，不直接推导配置。 | D6: 车主：请回顾最近一周的出行，从一个普通工作日开始讲起。 意向者：请回顾最近一周您实际怎样出行，包括使用其他车辆或交通方式的情况。 | E6: 1. 出行目的、交通方式、同行者及物品 2. 工作日与休息日差异；这一周是否典型 3. 购车前后变化或未来计划另列，说明依据 | F6: 按研究目的选用；有实际经历先谈经历，设想单独记录。 观察/活动：先还原实际出行，未来预期另列。FGD可个人先填时间线再讨论；IHV结合实际观察核对。 原追问4条：在“原追问审阅”按题卡编号筛选；详情保留在该表，不能把全部追问逐项念出。 | G6: 2C用户本人提纲：按生活背景—经历—选择—方案的顺序呈现。采用已讨论的M2样板；事实与设想分开，允许无困难，观察与产品方案分别执行。 原编号题：7条；在“原题映射”按本题编号检索。 | H6: 同意
A7: Q-M2.1-02 | B7: C2 高频使用场景 按需选择 FGD：可用 IHV：可用 | C7: 识别高频任务的强度与约束；与低频关键任务分开，支持场景优先级判断。 | D7: 车主：刚才这些出行中，哪一种发生最多？请具体讲一次。 意向者：刚才这些实际出行中，哪一种发生最多？ | E7: 1. 一周频次、单次里程及时长的范围 2. 估计值或记录值，堵车等造成的差异 3. 若未来用途不同，另记预计频次及依据 | F7: 按研究目的选用；有实际经历先谈经历，设想单独记录。 观察/活动：先还原实际出行，未来预期另列。FGD可个人先填时间线再讨论；IHV结合实际观察核对。 原追问5条：在“原追问审阅”按题卡编号筛选；详情保留在该表，不能把全部追问逐项念出。 | G7: 2C用户本人提纲：按生活背景—经历—选择—方案的顺序呈现。采用已讨论的M2样板；事实与设想分开，允许无困难，观察与产品方案分别执行。 原编号题：7条；在“原题映射”按本题编号检索。 | H7: 同意
A8: Q-M2.1-03 | B8: C2 高频使用场景 按需选择 FGD：可用 IHV：可用 | C8: 还原日常出行及频率，为高频场景和任务优先级提供证据。 | D8: 车主：车辆是否同时承担家庭、工作或营运任务？请各举一次。 意向者：车辆是否同时承担家庭、工作或营运任务？请各举一次。 | E8: 1. 任务冲突如何解决 2. 是否需要临时清理或调整座位 3. 主要与次要用途 | F8: 按研究目的选用；有实际经历先谈经历，设想单独记录。 原追问2条：在“原追问审阅”按题卡编号筛选；详情保留在该表，不能把全部追问逐项念出。 | G8: 2C用户本人提纲：按生活背景—经历—选择—方案的顺序呈现。保留研究任务，按对象区分问法；同义主问合并，细节保留为按条件追问。 原编号题：2条；在“原题映射”按本题编号检索。 | H8: 同意
A9: Q-M2.2-01 | B9: C2 关键与极端场景 核心信息 FGD：可用 IHV：可用 | C9: 识别低频但后果重大的任务，不以频次替代重要性。 | D9: 车主：有没有某次出行虽然不常发生，但对您特别重要？如果有，请讲讲。 意向者：有没有某次真实出行虽然不常发生，但对您特别重要？未来购车需要保留哪些能力？ | E9: 1. 具体任务、人员和时间压力 2. 最担心的后果 3. 与最高频场景分别记录 | F9: 按研究目的选用；有实际经历先谈经历，设想单独记录。 原追问1条：在“原追问审阅”按题卡编号筛选；详情保留在该表，不能把全部追问逐项念出。 | G9: 2C用户本人提纲：按生活背景—经历—选择—方案的顺序呈现。保留研究任务，按对象区分问法；同义主问合并，细节保留为按条件追问。 原编号题：3条；在“原题映射”按本题编号检索。 | H9: 同意
A10: Q-M2.2-02 | B10: C2 关键与极端场景 按需选择 FGD：可用 IHV：可用 | C10: 识别低频但后果重大的任务，不以频次替代重要性。 | D10: 车主：请回忆最近一次多人一起出行，完整讲讲从出发到结束的过程。 意向者：请回忆最近一次多人一起出行，完整讲讲从出发到结束的过程。 | E10: 1. 座位、行李、途中活动 2. 最顺利与最困难的环节 3. 原意向题先问真实经历再谈期待 | F10: 按研究目的选用；有实际经历先谈经历，设想单独记录。 原追问3条：在“原追问审阅”按题卡编号筛选；详情保留在该表，不能把全部追问逐项念出。 | G10: 2C用户本人提纲：按生活背景—经历—选择—方案的顺序呈现。保留研究任务，按对象区分问法；同义主问合并，细节保留为按条件追问。 原编号题：8条；在“原题映射”按本题编号检索。 | H10: 同意
A11: Q-M2.2-03 | B11: C2 关键与极端场景 按需选择 FGD：可用 IHV：可用 | C11: 识别低频但后果重大的任务，不以频次替代重要性。 | D11: 车主：您把什么样的行程算作长途？最近一次是如何计划和完成的？ 意向者：您把什么样的行程算作长途？最近一次是如何计划和完成的？ | E11: 1. 休息、补能、乘员活动 2. 是否改用别的交通方式 3. 有跨境经历再问通关和补能差异 | F11: 按研究目的选用；有实际经历先谈经历，设想单独记录。 【受访者确有跨境出行】通关、地图、网络、保险或补能是否改变行程安排？ 原追问5条：在“原追问审阅”按题卡编号筛选；详情保留在该表，不能把全部追问逐项念出。 | G11: 2C用户本人提纲：按生活背景—经历—选择—方案的顺序呈现。保留研究任务，按对象区分问法；同义主问合并，细节保留为按条件追问。 原编号题：3条；在“原题映射”按本题编号检索。 | H11: 同意
A12: Q-M2.2-04 | B12: C2 关键与极端场景 按需选择 FGD：可用 IHV：可用 | C12: 识别低频但后果重大的任务，不以频次替代重要性。 | D12: 车主：是否有过车辆不可用而改变行程的经历？如果有，请还原一次。 意向者：是否有过交通工具不可用而改变行程的经历？您当时怎样处理？ | E12: 1. 替代交通、额外费用、工作或接待损失 2. 恢复所需时间 3. 没有经历时记录无经历 | F12: 按研究目的选用；有实际经历先谈经历，设想单独记录。 原追问1条：在“原追问审阅”按题卡编号筛选；详情保留在该表，不能把全部追问逐项念出。 | G12: 2C用户本人提纲：按生活背景—经历—选择—方案的顺序呈现。保留研究任务，按对象区分问法；同义主问合并，细节保留为按条件追问。 原编号题：1条；在“原题映射”按本题编号检索。 | H12: 同意
A13: Q-M2.3-01 | B13: C2 乘员与装载 核心信息 FGD：可用 IHV：可用 | C13: 识别人、物和座椅之间的真实取舍，支持储物空间、装卸便利与座椅灵活性需求定义。 | D13: 车主：请讲最近一次带较多物品出行的经历，当时怎样安排人和物？ 意向者：请讲最近一次实际搬运或携带较多物品的经历，您使用什么交通方式，怎样完成？ | E13: 1. 物品形态/数量、同行人数、座椅状态 2. 装卸步骤、固定方式、装不下时的办法和代价 3. 频次；不是每位受访者都需回忆最大物品 | F13: 按研究目的选用；有实际经历先谈经历，设想单独记录。 【家用、有儿童或照护任务】儿童用品、推车或辅助器具如何装载？人员与物品冲突时怎样处理？ 【商务或营运】礼品、样品、展品或设备如何运输？包装与保管是否有特殊要求？ 观察/活动：IHV取得许可后，请演示日常装载或用现有物品说明；婴儿车仅在实际使用且物品可用时演示，不要求购买/搬来。概念评价另接M5，示卡编号不写死。 原追问5条：在“原追问审阅”按题卡编号筛选；详情保留在该表，不能把全部追问逐项念出。 | G13: 2C用户本人提纲：按生活背景—经历—选择—方案的顺序呈现。采用已讨论的M2样板；事实与设想分开，允许无困难，观察与产品方案分别执行。 原编号题：8条；在“原题映射”按本题编号检索。 | H13: 同意
A14: Q-M2.3-02 | B14: C2 乘员与装载 按需选择 FGD：可用 IHV：可用 | C14: 识别不同乘员进出车辆的操作障碍，为门开口、台阶、通道和座椅布局提供需求依据。 | D14: 车主：请回顾一次不同乘员上下车的过程，他们分别怎样进入和离开座位？ 意向者：请回顾您实际乘坐过的车辆，您和同行者怎样上下车？有哪些方便或不方便的地方？ | E14: 1. 仅对实际相关乘员问具体操作和是否需协助 2. 第三排题仅在实际车辆有第三排或项目测试第三排时展开 3. 先记录动作，再问本人感受；未在场乘员反馈标明转述 | F14: 按研究目的选用；有实际经历先谈经历，设想单独记录。 观察/活动：IHV在车辆静止且参与者愿意时观察；不要求儿童/行动不便者为测试重复困难动作。无实车时记录叙述证据，不声称实测。 原追问0条：在“原追问审阅”按题卡编号筛选；详情保留在该表，不能把全部追问逐项念出。 | G14: 2C用户本人提纲：按生活背景—经历—选择—方案的顺序呈现。采用已讨论的M2样板；事实与设想分开，允许无困难，观察与产品方案分别执行。 原编号题：1条；在“原题映射”按本题编号检索。 | H14: 同意
A15: Q-M2.3-03 | B15: C2 乘员与装载 按需选择 FGD：可用 IHV：可用 | C15: 识别人、物、座位与上下车操作的约束，支持空间需求定义。 | D15: 车主：您乘坐或驾驶时，什么样的坐姿最合适？ 意向者：在您实际驾驶或乘坐过的车辆中，怎样的坐姿适合您？请用具体体验说明。 | E15: 1. 视野、上下车、长途舒适性 2. 高低坐姿分别有什么体验 3. 驾驶与乘坐分开 | F15: 按研究目的选用；有实际经历先谈经历，设想单独记录。 原追问0条：在“原追问审阅”按题卡编号筛选；详情保留在该表，不能把全部追问逐项念出。 | G15: 2C用户本人提纲：按生活背景—经历—选择—方案的顺序呈现。保留研究任务，按对象区分问法；同义主问合并，细节保留为按条件追问。 原编号题：3条；在“原题映射”按本题编号检索。 | H15: 同意
A16: Q-M2.4-01 | B16: C2 停车、道路与气候 核心信息 FGD：可用 IHV：可用 | C16: 识别停车与进出车位的环境限制，支持外廓尺寸、转弯与开门空间需求；不预设大车必然不便。 | D16: 车主：您经常在哪里停车？请选一个常用地点，讲讲停车和离开的过程。 意向者：您目前出行涉及哪些停车安排？未来购车可用的停车地点，哪些已确认，哪些还不确定？ | E16: 1. 车位、通道、限高、转弯、开门与收费/寻找时间 2. 有困难再还原事件、后果与处理；允许顺利无困难 3. 尺寸实测、标牌、口述估计分开；购车影响另接M3.4 | F16: 按研究目的选用；有实际经历先谈经历，设想单独记录。 观察/活动：IHV取得许可后观察/测量；不为了研究驾驶车辆验证极限。当前停车条件与未来车型适配判断分开。 原追问7条：在“原追问审阅”按题卡编号筛选；详情保留在该表，不能把全部追问逐项念出。 | G16: 2C用户本人提纲：按生活背景—经历—选择—方案的顺序呈现。采用已讨论的M2样板；事实与设想分开，允许无困难，观察与产品方案分别执行。 原编号题：7条；在“原题映射”按本题编号检索。 | H16: 同意
A17: Q-M2.4-02 | B17: C2 停车、道路与气候 按需选择 FGD：可用 IHV：可用 | C17: 识别个人实际暴露的道路、停车与气候条件，支持适配需求。 | D17: 车主：常走的道路是什么样的？哪些路段最影响行驶和乘坐体验？ 意向者：常走的道路是什么样的？哪些路段最影响行驶和乘坐体验？ | E17: 1. 城市、高速、减速带、非铺装及坡道 2. 频次和具体问题 3. 不因道路良好跳过舒适性 | F17: 按研究目的选用；有实际经历先谈经历，设想单独记录。 原追问6条：在“原追问审阅”按题卡编号筛选；详情保留在该表，不能把全部追问逐项念出。 | G17: 2C用户本人提纲：按生活背景—经历—选择—方案的顺序呈现。保留研究任务，按对象区分问法；同义主问合并，细节保留为按条件追问。 原编号题：7条；在“原题映射”按本题编号检索。 | H17: 同意
... A26: Q-M2.5-05 | B26: C2 现有座舱与智驾使用 按需选择 FGD：可用 IHV：可用 | C26: 还原座舱操作任务、步骤和失败点，为交互改进提供依据。 | D26: 车主：车内不同乘员通常使用什么内容和设备？ 意向者：车内不同乘员通常使用什么内容和设备？ | E26: 1. 原装与自行安装 2. 前后排差异 3. 视频、音乐、工作等真实任务 | F26: 按研究目的选用；有实际经历先谈经历，设想单独记录。 【商务接待】后排乘员希望休息、工作还是娱乐？提供这些功能会不会干扰驾驶或交流？ 原追问8条：在“原追问审阅”按题卡编号筛选；详情保留在该表，不能把全部追问逐项念出。 | G26: 2C用户本人提纲：按生活背景—经历—选择—方案的顺序呈现。保留研究任务，按对象区分问法；同义主问合并，细节保留为按条件追问。 原编号题：8条；在“原题映射”按本题编号检索。 | H26: 同意
A27: Q-M2.5-06 | B27: C2 现有座舱与智驾使用 按需选择 FGD：可用 IHV：可用 | C27: 还原座舱操作任务、步骤和失败点，为交互改进提供依据。 | D27: 车主：车内哪些声音、灯光、材质或交互会让您觉得舒服、有氛围？哪些会让您不适或分心？ 意向者：车内哪些声音、灯光、材质或交互会让您觉得舒服、有氛围？哪些会让您不适或分心？ | E27: 1. 现有解决方式 2. 车内场景、使用频率 3. 哪些任务不需要上车 | F27: 按研究目的选用；有实际经历先谈经历，设想单独记录。 原追问4条：在“原追问审阅”按题卡编号筛选；详情保留在该表，不能把全部追问逐项念出。 | G27: 按审阅意见把“汽车氛围”改为可感知的声音、灯光、材质和交互。 原编号题：3条；在“原题映射”按本题编号检索。 | H27: 已按意见修改 | I27: 题目看不懂
A28: Q-M2.5-07 | B28: C2 现有座舱与智驾使用 按需选择 FGD：可用 IHV：可用 | C28: 还原座舱操作任务、步骤和失败点，为交互改进提供依据。 | D28: 车主：多人同时使用车内功能时，发生过怎样的情况？ 意向者：在实际乘坐经历中，多人同时使用车内功能时发生过什么？如果没有经历，未来需求另记。 | E28: 1. 音源、屏幕、温度或操作冲突 2. 最明显的事件 3. 如何协调 | F28: 按研究目的选用；有实际经历先谈经历，设想单独记录。 原追问3条：在“原追问审阅”按题卡编号筛选；详情保留在该表，不能把全部追问逐项念出。 | G28: 2C用户本人提纲：按生活背景—经历—选择—方案的顺序呈现。保留研究任务，按对象区分问法；同义主问合并，细节保留为按条件追问。 原编号题：4条；在“原题映射”按本题编号检索。 | H28: 同意
A29: Q-M2.5-08 | B29: C2 现有座舱与智驾使用 按需选择 FGD：可用 IHV：可用 | C29: 还原座舱操作任务、步骤和失败点，为交互改进提供依据。 | D29: 车主：哪些人使用现有车内系统时比较容易或困难？ 意向者：哪些人使用现有车内系统时比较容易或困难？ | E29: 1. 具体任务和失败步骤 2. 与经验、语言、身体条件的关系 3. 不预设女性或老人必然困难 | F29: 按研究目的选用；有实际经历先谈经历，设想单独记录。 原追问2条：在“原追问审阅”按题卡编号筛选；详情保留在该表，不能把全部追问逐项念出。 | G29: 2C用户本人提纲：按生活背景—经历—选择—方案的顺序呈现。保留研究任务，按对象区分问法；同义主问合并，细节保留为按条件追问。 原编号题：2条；在“原题映射”按本题编号检索。 | H29: 同意
A30: Q-M2.6-01 | B30: C2 痛点后果与替代办法 按需选择 FGD：可用 IHV：可用 | C30: 辨别满意来源、困难后果和替代办法，为需求排序提供依据。 | D30: 车主：回顾目前的出行或用车体验，最满意和最不满意的分别是什么？ 意向者：回顾目前的出行或用车体验，最满意和最不满意的分别是什么？ | E30: 1. 各举具体事件 2. 是否影响继续使用或下次选择 3. 先自发回答再补提示 | F30: 按研究目的选用；有实际经历先谈经历，设想单独记录。 原追问1条：在“原追问审阅”按题卡编号筛选；详情保留在该表，不能把全部追问逐项念出。 | G30: 2C用户本人提纲：按生活背景—经历—选择—方案的顺序呈现。保留研究任务，按对象区分问法；同义主问合并，细节保留为按条件追问。 原编号题：3条；在“原题映射”按本题编号检索。 | H30: 同意
A31: Q-M2.6-02 | B31: C2 痛点后果与替代办法 核心信息 FGD：可用 IHV：可用 | C31: 识别未满足需求的发生机制、影响及替代办法，为需求优先级提供证据，不把抱怨数量当市场发生率。 | D31: 车主：回顾刚才的出行，有没有您希望改善的地方？如果有，请选一件具体讲讲。 意向者：在您目前真实的出行中，有没有希望改善的地方？请用一次实际经历说明。 | E31: 1. 触发条件、发生频次、受影响者 2. 时间、费用、任务或感受上的后果 3. 已经采用的办法、成本、仍未解决的部分；什么改变才算解决 | F31: 按研究目的选用；有实际经历先谈经历，设想单独记录。 观察/活动：不强迫每人给痛点；使用困难、成交异议和售后处理分别标注。经销商只谈购买犹豫时转M3，不当作真实使用体验。 原追问4条：在“原追问审阅”按题卡编号筛选；详情保留在该表，不能把全部追问逐项念出。 | G31: 2C用户本人提纲：按生活背景—经历—选择—方案的顺序呈现。采用已讨论的M2样板；事实与设想分开，允许无困难，观察与产品方案分别执行。 原编号题：2条；在“原题映射”按本题编号检索。 | H31: 同意
A32: Q-M2.6-03 | B32: C2 痛点后果与替代办法 按需选择 FGD：可用 IHV：可用 | C32: 辨别满意来源、困难后果和替代办法，为需求排序提供依据。 | D32: 车主：车内操作有没有您希望改善的地方？如果有，请还原最近一次。 意向者：在实际体验过的车内操作中，有没有希望改善的地方？如果有，请还原一次。 | E32: 1. 步骤与结果 2. 替代方式 3. 达到什么水平就足够 4. 若前面已讲则核验不重问 | F32: 按研究目的选用；有实际经历先谈经历，设想单独记录。 原追问3条：在“原追问审阅”按题卡编号筛选；详情保留在该表，不能把全部追问逐项念出。 | G32: 2C用户本人提纲：按生活背景—经历—选择—方案的顺序呈现。保留研究任务，按对象区分问法；同义主问合并，细节保留为按条件追问。 原编号题：4条；在“原题映射”按本题编号检索。 | H32: 同意
A33: Q-M2.6-04 | B33: C2 痛点后果与替代办法 按需选择 FGD：可用 IHV：可用 | C33: 辨别满意来源、困难后果和替代办法，为需求排序提供依据。 | D33: 车主：现在使用的车辆或出行安排中，哪一项最让您觉得值得？ 意向者：现在使用的车辆或出行安排中，哪一项最让您觉得值得？ | E33: 1. 为什么值得 2. 经常使用还是关键时刻有用 3. 替代它需要什么 | F33: 按研究目的选用；有实际经历先谈经历，设想单独记录。 原追问0条：在“原追问审阅”按题卡编号筛选；详情保留在该表，不能把全部追问逐项念出。 | G33: 2C用户本人提纲：按生活背景—经历—选择—方案的顺序呈现。保留研究任务，按对象区分问法；同义主问合并，细节保留为按条件追问。 原编号题：1条；在“原题映射”按本题编号检索。 | H33: 同意
A34: Q-M2.7-01 | B34: C2 持有成本与服务体验 按需选择 FGD：可用 IHV：可用 | C34: 识别持有支出与服务负担，为总成本和服务方案提供依据。 | D34: 车主：请估算最近一个月或一年的用车支出，并说明计算口径。 意向者：请估算目前出行的费用，并说明未来购车后哪些支出最在意。 | E34: 1. 选择一个明确期间，按能源、停车、保险、保养维修等分别估算 2. 记录金额、币种、支付周期及账单或估计来源 3. 首购意向者记录当前交通支出，未来用车预算另列；不默认电车更省 | F34: 按研究目的选用；有实际经历先谈经历，设想单独记录。 原追问0条：在“原追问审阅”按题卡编号筛选；详情保留在该表，不能把全部追问逐项念出。 | G34: 2C用户本人提纲：按生活背景—经历—选择—方案的顺序呈现。保留研究任务，按对象区分问法；同义主问合并，细节保留为按条件追问。 原编号题：3条；在“原题映射”按本题编号检索。 | H34: 同意
A35: Q-M2.7-02 | B35: C2 持有成本与服务体验 按需选择 FGD：可用 IHV：可用 | C35: 识别持有支出与服务负担，为总成本和服务方案提供依据。 | D35: 车主：您实际比较过不同用车方案的花费吗？结果如何？ 意向者：您实际比较过不同交通或用车方案的花费吗？如果有，请说明口径；未来预计支出另外记录。 | E35: 1. 同里程与同期间口径 2. 是否包含车价、利息和折旧 3. 没有比较则不要求编节省数 | F35: 按研究目的选用；有实际经历先谈经历，设想单独记录。 原追问3条：在“原追问审阅”按题卡编号筛选；详情保留在该表，不能把全部追问逐项念出。 | G35: 2C用户本人提纲：按生活背景—经历—选择—方案的顺序呈现。保留研究任务，按对象区分问法；同义主问合并，细节保留为按条件追问。 原编号题：2条；在“原题映射”按本题编号检索。 | H35: 同意
A36: Q-M2.7-03 | B36: C2 持有成本与服务体验 按需选择 FGD：可用 IHV：可用 | C36: 识别持有支出与服务负担，为总成本和服务方案提供依据。 | D36: 车主：请回顾最近一次保养或维修，从预约到取车发生了什么？ 意向者：如果您过去有车辆保养或维修经历，请举最近一次；否则，您对未来服务有什么要求？ | E36: 1. 等待、距离、费用、沟通和替代车 2. 最不能接受的环节 3. 无经历记录未知 | F36: 按研究目的选用；有实际经历先谈经历，设想单独记录。 原追问2条：在“原追问审阅”按题卡编号筛选；详情保留在该表，不能把全部追问逐项念出。 | G36: 2C用户本人提纲：按生活背景—经历—选择—方案的顺序呈现。保留研究任务，按对象区分问法；同义主问合并，细节保留为按条件追问。 原编号题：1条；在“原题映射”按本题编号检索。 | H36: 同意
A37: Q-M2.7-04 | B37: C2 持有成本与服务体验 按需选择 FGD：可用 IHV：可用 | C37: 识别持有支出与服务负担，为总成本和服务方案提供依据。 | D37: 车主：车辆使用一段时间后，哪些部位变化最明显？ | E37: 1. 内饰磨损、异响、清洁、配饰与改装 2. 对品质或残值判断的影响 | F37: 仅有对应已购车/使用经历者。 原追问1条：在“原追问审阅”按题卡编号筛选；详情保留在该表，不能把全部追问逐项念出。 | G37: 2C用户本人提纲：按生活背景—经历—选择—方案的顺序呈现。保留研究任务，按对象区分问法；同义主问合并，细节保留为按条件追问。 原编号题：2条；在“原题映射”按本题编号检索。 | H37: 同意
A38: Q-M8.1-01 | B38: C2 基础设施与能源环境 核心信息 FGD：可用 IHV：可用 | C38: 识别地区与个体基础设施差异，为动力适配提供前提条件。 | D38: 车主：您实际熟悉的区域，停车、能源或补能条件怎样影响日常出行？ 意向者：您目前能够使用或已确认的停车、能源和补能条件有哪些？哪些还不清楚？ | E38: 1. 城市内差异 2. 私人/公共设施分开 3. 本人经历、客户转述、资料分别记录 | F38: 按研究目的选用；有实际经历先谈经历，设想单独记录。 原追问3条：在“原追问审阅”按题卡编号筛选；详情保留在该表，不能把全部追问逐项念出。 | G38: 2C用户本人提纲：按生活背景—经历—选择—方案的顺序呈现。地域条件、政策与工程事实需核验；个体经历、当地资料和受访者推测分别记录。 原编号题：2条；在“原题映射”按本题编号检索。 | H38: 同意
A39: Q-M8.3-01 | B39: C2 语言与数字生态 核心信息 FGD：可用 IHV：可用 | C39: 识别语言、地图、账户及内容服务的实际任务需求。 | D39: 车主：哪些语言、地图、内容或连接服务对实际用车最重要？ 意向者：哪些语言、地图、内容或连接服务对实际用车最重要？ | E39: 1. 由受访者自发指出 2. 目前替代办法 3. 对离线、账户、支付或混合语言的要求 | F39: 按研究目的选用；有实际经历先谈经历，设想单独记录。 原追问4条：在“原追问审阅”按题卡编号筛选；详情保留在该表，不能把全部追问逐项念出。 | G39: 2C用户本人提纲：按生活背景—经历—选择—方案的顺序呈现。地域条件、政策与工程事实需核验；个体经历、当地资料和受访者推测分别记录。 原编号题：2条；在“原题映射”按本题编号检索。 | H39: 同意
A40: Q-M8.3-02 | B40: C2 语言与数字生态 按需选择 FGD：可用 IHV：可用 | C40: 识别语言、地图、账户及内容服务的实际任务需求。 | D40: 车主：现有车内系统有哪些本地化不到位的地方？ 意向者：现有车内系统有哪些本地化不到位的地方？ | E40: 1. 原词/界面/具体任务 2. 翻译、地址、单位、语音和内容 3. 不假定每个市场问题相同 | F40: 按研究目的选用；有实际经历先谈经历，设想单独记录。 原追问0条：在“原追问审阅”按题卡编号筛选；详情保留在该表，不能把全部追问逐项念出。 | G40: 2C用户本人提纲：按生活背景—经历—选择—方案的顺序呈现。地域条件、政策与工程事实需核验；个体经历、当地资料和受访者推测分别记录。 原编号题：0条；在“原题映射”按本题编号检索。 本次补充的新题。 | H40: 同意
A41: Q-M2.6-05 | B41: C2 痛点后果与替代办法 按需选择 FGD：可用 IHV：可用 | C41: 辨别满意来源、困难后果和替代办法，为需求排序提供依据。 | D41: 车主：现有车辆在使用中有哪些让您觉得不方便、费时间或需要额外处理的问题？ 意向者：现有车辆在使用中有哪些让您觉得不方便、费时间或需要额外处理的问题？ | E41: 1. 用材、气味、噪声、整洁和乘员互动的具体表现 2. 本人感受与乘客反馈分开 3. 对接待或出行结果有何影响 | F41: 按研究目的选用；有实际经历先谈经历，设想单独记录。 原追问1条：在“原追问审阅”按题卡编号筛选；详情保留在该表，不能把全部追问逐项念出。 | G41: 按审阅意见改为日常语言，避免抽象的痛点表达。 原编号题：1条；在“原题映射”按本题编号检索。 | H41: 已按意见修改 | I41: 汽车氛围有点表述不清楚

Sheet 2C-03 购买旅程与考虑因素
A2: 2C-03 购买旅程与考虑因素
A3: 23张题卡。2C：消费者本人及家庭的真实经历。黄色列供你填写；核心信息已回答就不重复问。
A5: 题卡编号 | B5: 子模块与适用方法 | C5: 研究目的与边界 | D5: 主问：按对象选用 | E5: 核心追问：覆盖信息 | F5: 触发条件与观察任务 | G5: 归并调整与来源 | H5: 确认状态 | I5: 你的修改意见
A6: Q-M3.1-01 | B6: C3 触发事件与预算 核心信息 FGD：可用 IHV：可用 | C6: 区分购车触发、预算形成与实际支出，明确需求启动条件。 | D6: 车主：您上一辆车是什么车型、用了多久？ 最初是什么事情让您产生这次买车或换车的想法？ 意向者：您目前主要使用什么车、用了多久？ 最初是什么事情让您产生这次买车或换车的想法？ | E6: 1. 生活、工作或使用条件变化 2. 首购/增购/换购 3. 触发与最终选择分开 | F6: 按研究目的选用；有实际经历先谈经历，设想单独记录。 原追问7条：在“原追问审阅”按题卡编号筛选；详情保留在该表，不能把全部追问逐项念出。 | G6: 按审阅意见补充上一辆车或当前车辆及使用时长。 原编号题：7条；在“原题映射”按本题编号检索。 | H6: 已按意见修改 | I6: 上一辆车是什么车，用了多久，这信息可能要增加
A7: Q-M3.1-02 | B7: C3 触发事件与预算 按需选择 FGD：可用 IHV：可用 | C7: 区分购车触发、预算形成与实际支出，明确需求启动条件。 | D7: 车主：购车预算是怎样定下来的？后来有过变化吗？ 意向者：目前的购车预算怎样定下来的？哪些条件可能让它变化？ | E7: 1. 谁定预算 2. 金额、币种、是否含税费 3. 上调或下调的实际原因 | F7: 按研究目的选用；有实际经历先谈经历，设想单独记录。 原追问4条：在“原追问审阅”按题卡编号筛选；详情保留在该表，不能把全部追问逐项念出。 | G7: 2C用户本人提纲：按生活背景—经历—选择—方案的顺序呈现。保留研究任务，按对象区分问法；同义主问合并，细节保留为按条件追问。 原编号题：3条；在“原题映射”按本题编号检索。 | H7: 同意
A8: Q-M3.1-03 | B8: C3 触发事件与预算 按需选择 FGD：可用 IHV：可用 | C8: 区分购车触发、预算形成与实际支出，明确需求启动条件。 | D8: 车主：当时购车的实际落地支出是多少？请说明包括哪些费用。 | E8: 1. 记录币种、成交日期、车价、税费、保险和金融费用；已含项目不重复相加 2. 预算与实际支出有哪些差异，为什么 3. 如评价是否值得，另外记录判断依据，不与金额混成一个答案 | F8: 仅有对应已购车/使用经历者。 原追问3条：在“原追问审阅”按题卡编号筛选；详情保留在该表，不能把全部追问逐项念出。 | G8: 2C用户本人提纲：按生活背景—经历—选择—方案的顺序呈现。保留研究任务，按对象区分问法；同义主问合并，细节保留为按条件追问。 原编号题：3条；在“原题映射”按本题编号检索。 | H8: 同意
A9: Q-M3.2-01 | B9: C3 信息源与候选清单 核心信息 FGD：可用 IHV：可用 | C9: 还原信息来源与候选变化，为竞争范围和触点选择提供依据。 | D9: 车主：在本次选车过程中，您考虑过哪些车型？候选清单如何变化？ 意向者：在本次选车过程中，您考虑过哪些车型？候选清单如何变化？ | E9: 1. 最初与最后名单 2. 跨车身/动力/价格带 3. 没有考虑过的不强行评价 | F9: 按研究目的选用；有实际经历先谈经历，设想单独记录。 原追问7条：在“原追问审阅”按题卡编号筛选；详情保留在该表，不能把全部追问逐项念出。 | G9: 2C用户本人提纲：按生活背景—经历—选择—方案的顺序呈现。保留研究任务，按对象区分问法；同义主问合并，细节保留为按条件追问。 原编号题：11条；在“原题映射”按本题编号检索。 | H9: 同意
A10: Q-M3.2-02 | B10: C3 信息源与候选清单 按需选择 FGD：可用 IHV：可用 | C10: 还原信息来源与候选变化，为竞争范围和触点选择提供依据。 | D10: 车主：候选清单里最优先的一款是什么？为什么？ 意向者：候选清单里最优先的一款是什么？为什么？ | E10: 1. 是否后来改变排序 2. 具体吸引点 3. 品牌与产品因素分别记录 | F10: 按研究目的选用；有实际经历先谈经历，设想单独记录。 原追问4条：在“原追问审阅”按题卡编号筛选；详情保留在该表，不能把全部追问逐项念出。 | G10: 2C用户本人提纲：按生活背景—经历—选择—方案的顺序呈现。保留研究任务，按对象区分问法；同义主问合并，细节保留为按条件追问。 原编号题：4条；在“原题映射”按本题编号检索。 | H10: 同意
A11: Q-M3.2-03 | B11: C3 信息源与候选清单 按需选择 FGD：可用 IHV：可用 | C11: 还原信息来源与候选变化，为竞争范围和触点选择提供依据。 | D11: 车主：哪些信息来源真正影响了您的选车？请讲一次影响决定的信息。 意向者：哪些信息来源真正影响了您的选车？请讲一次影响决定的信息。 | E11: 1. 主动搜索、亲友、门店或媒体 2. 接触与信任分别记录 3. AI信息如实际使用再问 | F11: 按研究目的选用；有实际经历先谈经历，设想单独记录。 原追问4条：在“原追问审阅”按题卡编号筛选；详情保留在该表，不能把全部追问逐项念出。 | G11: 2C用户本人提纲：按生活背景—经历—选择—方案的顺序呈现。保留研究任务，按对象区分问法；同义主问合并，细节保留为按条件追问。 原编号题：6条；在“原题映射”按本题编号检索。 | H11: 同意
A12: Q-M3.2-04 | B12: C3 信息源与候选清单 按需选择 FGD：可用 IHV：可用 | C12: 还原信息来源与候选变化，为竞争范围和触点选择提供依据。 | D12: 车主：对您真正了解或体验过的候选车型，优缺点分别是什么？ 意向者：对您真正了解或体验过的候选车型，优缺点分别是什么？ | E12: 1. 体验来源 2. 逐车型比较同一维度 3. 未体验仅记录印象，不当实测 | F12: 按研究目的选用；有实际经历先谈经历，设想单独记录。 原追问13条：在“原追问审阅”按题卡编号筛选；详情保留在该表，不能把全部追问逐项念出。 | G12: 2C用户本人提纲：按生活背景—经历—选择—方案的顺序呈现。保留研究任务，按对象区分问法；同义主问合并，细节保留为按条件追问。 原编号题：20条；在“原题映射”按本题编号检索。 | H12: 同意
A13: Q-M3.3-01 | B13: C3 决策链与试驾 核心信息 FGD：可用 IHV：可用 | C13: 还原决策节点和体验验证，识别流程卡点与服务改进机会。 | D13: 车主：请按时间顺序还原从产生购车想法到当前阶段的关键节点。 意向者：请按时间顺序还原从产生购车想法到当前阶段的关键节点。 | E13: 1. 开始搜索、到店、试驾、决定、下单、交车 2. 未发生节点记录计划 3. 卡在哪一步 | F13: 按研究目的选用；有实际经历先谈经历，设想单独记录。 观察/活动：画购车时间轴，标已发生节点与未来计划；让受访者自行补充，主持人只核对遗漏。 原追问8条：在“原追问审阅”按题卡编号筛选；详情保留在该表，不能把全部追问逐项念出。 | G13: 2C用户本人提纲：按生活背景—经历—选择—方案的顺序呈现。保留研究任务，按对象区分问法；同义主问合并，细节保留为按条件追问。 原编号题：10条；在“原题映射”按本题编号检索。 | H13: 同意
A14: Q-M3.3-02 | B14: C3 决策链与试驾 按需选择 FGD：可用 IHV：可用 | C14: 还原决策节点和体验验证，识别流程卡点与服务改进机会。 | D14: 车主：到店看车或试驾时，您重点验证了什么？ 意向者：到店看车或试驾时，您重点验证了什么？ | E14: 1. 谁一起参与 2. 具体区域、功能或路段 3. 是否改变原有判断 4. 没试驾则问原因 | F14: 按研究目的选用；有实际经历先谈经历，设想单独记录。 原追问4条：在“原追问审阅”按题卡编号筛选；详情保留在该表，不能把全部追问逐项念出。 | G14: 2C用户本人提纲：按生活背景—经历—选择—方案的顺序呈现。保留研究任务，按对象区分问法；同义主问合并，细节保留为按条件追问。 原编号题：11条；在“原题映射”按本题编号检索。 | H14: 同意
A15: Q-M3.3-03 | B15: C3 决策链与试驾 按需选择 FGD：可用 IHV：可用 | C15: 还原决策节点和体验验证，识别流程卡点与服务改进机会。 | D15: 车主：您是怎样选择门店或购买渠道的？ 意向者：您是怎样选择门店或购买渠道的？ | E15: 1. 距离、服务、价格、口碑和网络覆盖 2. 选中与放弃的实际原因 | F15: 按研究目的选用；有实际经历先谈经历，设想单独记录。 原追问4条：在“原追问审阅”按题卡编号筛选；详情保留在该表，不能把全部追问逐项念出。 | G15: 2C用户本人提纲：按生活背景—经历—选择—方案的顺序呈现。保留研究任务，按对象区分问法；同义主问合并，细节保留为按条件追问。 原编号题：2条；在“原题映射”按本题编号检索。 | H15: 同意
A16: Q-M3.3-04 | B16: C3 决策链与试驾 按需选择 FGD：可用 IHV：可用 | C16: 还原决策节点和体验验证，识别流程卡点与服务改进机会。 | D16: 车主：请回顾一次购车服务经历，哪些环节影响了您的决定？ 意向者：在已经发生的看车或咨询过程中，哪些服务影响了您的判断？没有发生则记录尚未到店。 | E16: 1. 销售解释、试驾、承诺兑现 2. 是否改变候选、下单时间或品牌信任 | F16: 按研究目的选用；有实际经历先谈经历，设想单独记录。 原追问2条：在“原追问审阅”按题卡编号筛选；详情保留在该表，不能把全部追问逐项念出。 | G16: 2C用户本人提纲：按生活背景—经历—选择—方案的顺序呈现。保留研究任务，按对象区分问法；同义主问合并，细节保留为按条件追问。 原编号题：1条；在“原题映射”按本题编号检索。 | H16: 同意
A17: Q-M3.4-01 | B17: C3 购车考虑因素 按需选择 FGD：可用 IHV：可用 | C17: 识别消费者选车时的考虑因素及优先级，并为后续产品取舍提供依据。 | D17: 车主：选车时您最看重哪些因素？请先自由列出，再选最重要的三项。 意向者：选车时您最看重哪些因素？请先自由列出，再选最重要的三项。 | E17: 1. 每项需要达到什么程度 2. 是否存在一票否决项 3. 不要先把全部属性读给受访者 | F17: 按研究目的选用；有实际经历先谈经历，设想单独记录。 原追问6条：在“原追问审阅”按题卡编号筛选；详情保留在该表，不能把全部追问逐项念出。 | G17: 将原有权衡题明确命名为“购车考虑因素”，便于提纲生成时直接选用。 原编号题：5条；在“原题映射”按本题编号检索。 | H17: 已按意见修改
A18: Q-M3.4-02 | B18: C3 购车考虑因素与取舍 核心信息 FGD：可用 IHV：可用 | C18: 辨别决定因素、否决条件和真实妥协，避免把口头偏好等同选择。 | D18: 车主：最终选择这辆车最关键的原因是什么？ 意向者：目前最倾向的车型是哪个？哪些理由让它排在前面，哪些条件还没确认？ | E18: 1. 与最后仍在比较的备选相比，哪项差异最终起作用 2. 区分事前最重要因素与最后促成决定的事件 3. 意向者只谈目前排序和未确认条件，不追问已成交结果 | F18: 按研究目的选用；有实际经历先谈经历，设想单独记录。 原追问6条：在“原追问审阅”按题卡编号筛选；详情保留在该表，不能把全部追问逐项念出。 | G18: 2C用户本人提纲：按生活背景—经历—选择—方案的顺序呈现。保留研究任务，按对象区分问法；同义主问合并，细节保留为按条件追问。 原编号题：11条；在“原题映射”按本题编号检索。 | H18: 同意
... A27: Q-M8.2-01 | B27: C3 补贴与政策影响 核心信息 FGD：可用 IHV：可用 | C27: 区分政策知晓、资格、实际享受和决策影响，保留地区日期及核验来源。 | D27: 车主：您知道当地有哪些购车补贴、税费减免、牌照或用车优惠？这次是否实际申请或享受过？ 意向者：您知道当地有哪些购车补贴、税费减免、牌照或用车优惠？哪些会影响您的购车考虑？ | E27: 1. 政策名称、地区、时间与核验来源 2. 知晓、符合资格、实际享受分开 | F27: 先问自发认知；只有项目组已核验当地政策名称、适用车型和有效期后，才提示具体政策。 【已核验当地政策且受访者知晓】当时是否实际申请或享受过该政策？是否改变购买时间、预算或动力选择？ 原追问11条：在“原追问审阅”按题卡编号筛选；详情保留在该表，不能把全部追问逐项念出。 | G27: 补足2C补贴问题，并防止把历史政策当作当前事实。 原编号题：5条；在“原题映射”按本题编号检索。 | H27: 已按意见修改
A28: Q-M8.2-02 | B28: C3 补贴与政策影响 按需选择 FGD：可用 IHV：可用 | C28: 区分政策知晓、资格、实际享受和决策影响，保留地区日期及核验来源。 | D28: 车主：如果补贴或税费优惠增加、减少或取消，您的购车时间、预算、动力形式或车型选择会怎样变化？ 意向者：如果补贴或税费优惠增加、减少或取消，您的购车时间、预算、动力形式或车型选择会怎样变化？ | E28: 1. 前后期间、具体订单 2. 其他影响因素 3. 没有证据则记录为推测 | F28: 仅当受访者知晓或项目已提供经核验的政策情境时触发；记录实际影响和假设反应。 原追问0条：在“原追问审阅”按题卡编号筛选；详情保留在该表，不能把全部追问逐项念出。 | G28: 按审阅意见改为明确的补贴变化情境。 原编号题：0条；在“原题映射”按本题编号检索。 本次补充的新题。 | H28: 已按意见修改 | I28: 看不懂

Sheet 2C-04 动力与补能
A2: 2C-04 动力与补能
A3: 20张题卡。2C：消费者本人及家庭的真实经历。黄色列供你填写；核心信息已回答就不重复问。
A5: 题卡编号 | B5: 子模块与适用方法 | C5: 研究目的与边界 | D5: 主问：按对象选用 | E5: 核心追问：覆盖信息 | F5: 触发条件与观察任务 | G5: 归并调整与来源 | H5: 确认状态 | I5: 你的修改意见
A6: Q-M4.1-01 | B6: C4 动力理解与选择 核心信息 FGD：可用 IHV：可用 | C6: 理解动力认知及选择条件，区分事实限制与印象顾虑。 | D6: 车主：您知道哪些汽车动力形式？对燃油、混动、插混和纯电分别有什么理解？ 意向者：您知道哪些汽车动力形式？对燃油、混动、插混和纯电分别有什么理解？ | E6: 1. 先自发理解再解释技术 2. 选车流程中先定动力还是车型 3. 允许没有明确偏好 | F6: 按研究目的选用；有实际经历先谈经历，设想单独记录。 原追问6条：在“原追问审阅”按题卡编号筛选；详情保留在该表，不能把全部追问逐项念出。 | G6: 按审阅意见先测自发认知，再进入动力选择。 原编号题：11条；在“原题映射”按本题编号检索。 | H6: 已按意见修改 | I6: 要先问他，你知道哪些动力形式
A7: Q-M4.1-02 | B7: C4 动力理解与选择 按需选择 FGD：可用 IHV：可用 | C7: 理解动力认知及选择条件，区分事实限制与印象顾虑。 | D7: 车主：哪些具体原因让您考虑或放弃某种动力形式？ 意向者：哪些具体原因让您考虑或放弃某种动力形式？ | E7: 1. 真实使用条件、成本、信任、习惯 2. 已经经历与听说的风险分开 | F7: 按研究目的选用；有实际经历先谈经历，设想单独记录。 原追问4条：在“原追问审阅”按题卡编号筛选；详情保留在该表，不能把全部追问逐项念出。 | G7: 2C用户本人提纲：按生活背景—经历—选择—方案的顺序呈现。保留研究任务，按对象区分问法；同义主问合并，细节保留为按条件追问。 原编号题：7条；在“原题映射”按本题编号检索。 | H7: 同意
A8: Q-M4.1-03 | B8: C4 动力理解与选择 按需选择 FGD：可用 IHV：可用 | C8: 理解动力认知及选择条件，区分事实限制与印象顾虑。 | D8: 车主：您如何理解增程式动力？了解清楚后有哪些接受点和顾虑？ 意向者：您如何理解增程式动力？了解清楚后有哪些接受点和顾虑？ | E8: 1. 先记录原有认知 2. 主持人使用中性的已审核说明 3. 与自身任务相关而非技术偏好问答 | F8: 按研究目的选用；有实际经历先谈经历，设想单独记录。 原追问3条：在“原追问审阅”按题卡编号筛选；详情保留在该表，不能把全部追问逐项念出。 | G8: 2C用户本人提纲：按生活背景—经历—选择—方案的顺序呈现。保留研究任务，按对象区分问法；同义主问合并，细节保留为按条件追问。 原编号题：3条；在“原题映射”按本题编号检索。 | H8: 同意
A9: Q-M4.2-01 | B9: C4 实际补能条件 核心信息 FGD：可用 IHV：可用 | C9: 还原补能流程、设施条件及成本，支持补能服务与使用条件定义。 | D9: 车主：请描述您的充电习惯：通常剩余多少电会充、多久充一次、主要在哪里充？最近一次充电是怎样的？总体方便吗？ | E9: 1. 地点、频次、起止电量、车辆停留与本人等待 2. 日常家充/公共充电比例 3. 对行程影响 | F9: 实际充电题：有BEV/PHEV/增程充电经历。 原追问4条：在“原追问审阅”按题卡编号筛选；详情保留在该表，不能把全部追问逐项念出。 | G9: 按审阅意见重组为充电时点、频率、场所、最近一次经历和便利性。 原编号题：6条；在“原题映射”按本题编号检索。 | H9: 已按意见修改 | I9: 请你描述下你充电的i习惯（20%一看到就充电），充电的频率（每天），充电的场所（家or公司）？最近一次是怎样的？。。。要重新组织下语言，总体上是否方便
A10: Q-M4.2-02 | B10: C4 实际补能条件 按需选择 FGD：可用 IHV：可用 | C10: 还原补能流程、设施条件及成本，支持补能服务与使用条件定义。 | D10: 车主：您实际使用过公共快充吗？请讲最近一次经历。 | E10: 1. 找桩、排队、可用性、支付与充电结果 2. 担忧与实际故障区分 3. 未使用则问原因 | F10: 实际充电题：有BEV/PHEV/增程充电经历。 原追问2条：在“原追问审阅”按题卡编号筛选；详情保留在该表，不能把全部追问逐项念出。 | G10: 2C用户本人提纲：按生活背景—经历—选择—方案的顺序呈现。保留研究任务，按对象区分问法；同义主问合并，细节保留为按条件追问。 原编号题：3条；在“原题映射”按本题编号检索。 | H10: 同意
A11: Q-M4.2-03 | B11: C4 实际补能条件 按需选择 FGD：可用 IHV：可用 | C11: 还原补能流程、设施条件及成本，支持补能服务与使用条件定义。 | D11: 车主：实际充电时，哪些环节符合预期，哪些没有？如有问题，请讲一次。 | E11: 1. 最近一次、频率、温度或设备条件 2. 是否更换地点 3. 不先暗示过热或故障 | F11: 实际充电题：有BEV/PHEV/增程充电经历。 原追问0条：在“原追问审阅”按题卡编号筛选；详情保留在该表，不能把全部追问逐项念出。 | G11: 2C用户本人提纲：按生活背景—经历—选择—方案的顺序呈现。保留研究任务，按对象区分问法；同义主问合并，细节保留为按条件追问。 原编号题：4条；在“原题映射”按本题编号检索。 | H11: 同意
A12: Q-M4.2-04 | B12: C4 实际补能条件 核心信息 FGD：可用 IHV：可用 | C12: 还原补能流程、设施条件及成本，支持补能服务与使用条件定义。 | D12: 车主：您家、公司或其他日常停车地点是否可以安装充电桩？目前有哪些限制？ 意向者：您家、公司或其他日常停车地点是否可以安装充电桩？目前有哪些限制？ | E12: 1. 是否装桩 2. 车位、供电、许可和费用 3. 不清楚功率时允许未知，不把三相电当默认条件 | F12: 现有或未来有外接充电需求者均可问条件；油车/意向者不问从未发生的充电经历。未知条件记录待确认。 【具备安装意向或曾申请家充】是否需要停车场、物业或其他主体许可？申请过程怎样？不要预设所有公寓都限制安装。 观察/活动：IHV：在受访者愿意且安全的范围内观察停车与充电设施，不打开电气设备；参数只记能确认的内容。 原追问5条：在“原追问审阅”按题卡编号筛选；详情保留在该表，不能把全部追问逐项念出。 | G12: 按审阅意见使用家庭、公司等具体停车地点。 原编号题：8条；在“原题映射”按本题编号检索。 | H12: 已按意见修改 | I12: 您家、公司这些日常停车的地方是否可以安装充电桩？
A13: Q-M4.2-05 | B13: C4 实际补能条件 按需选择 FGD：可用 IHV：可用 | C13: 还原补能流程、设施条件及成本，支持补能服务与使用条件定义。 | D13: 车主：现有或了解过的交流充电方案，是否满足车辆停留期间的补能需要？ 意向者：现有或了解过的交流充电方案，是否满足车辆停留期间的补能需要？ | E13: 1. 已知车端接收能力、充电设施与供电条件；未知允许不答 2. 通常停车多久、起止电量或下一程所需里程 3. 不要求受访者自行换算功率、容量与充满时间；方案比较使用核验材料 | F13: 现有或未来有外接充电需求者均可问条件；油车/意向者不问从未发生的充电经历。未知条件记录待确认。 原追问4条：在“原追问审阅”按题卡编号筛选；详情保留在该表，不能把全部追问逐项念出。 | G13: 2C用户本人提纲：按生活背景—经历—选择—方案的顺序呈现。保留研究任务，按对象区分问法；同义主问合并，细节保留为按条件追问。 原编号题：6条；在“原题映射”按本题编号检索。 | H13: 同意
A14: Q-M4.2-06 | B14: C4 实际补能条件 按需选择 FGD：可用 IHV：可用 | C14: 还原补能流程、设施条件及成本，支持补能服务与使用条件定义。 | D14: 车主：请回顾最近一次加油或其他燃料补给的过程。 | E14: 1. 燃料种类、频次、距离、费用 2. 多燃料选择条件 3. 不默认乙醇普遍使用 | F14: 实际加油题：有ICE/HEV/PHEV/增程加油经历。 【市场确有多燃料选择且本人使用】是否在不同燃料之间切换？依据价格、可用性还是体验？ 原追问3条：在“原追问审阅”按题卡编号筛选；详情保留在该表，不能把全部追问逐项念出。 | G14: 2C用户本人提纲：按生活背景—经历—选择—方案的顺序呈现。保留研究任务，按对象区分问法；同义主问合并，细节保留为按条件追问。 原编号题：1条；在“原题映射”按本题编号检索。 | H14: 同意
A15: Q-M4.3-01 | B15: C4 续航与补能时间底线 核心信息 FGD：可用 IHV：可用 | C15: 连接行程、停车窗口和可用续航，提供技术取舍需求输入；不直接决定电气架构。 | D15: 车主：结合常见行程和最关键的一次远行，怎样的续航才够用？ 意向者：结合目前真实行程和已确定的未来任务，您期望怎样的续航？哪些要求还只是设想？ | E15: 1. 日常与极端需求分别记录 2. 可接受补能次数 3. 所说里程是实际可用还是标称 | F15: 按研究目的选用；有实际经历先谈经历，设想单独记录。 原追问6条：在“原追问审阅”按题卡编号筛选；详情保留在该表，不能把全部追问逐项念出。 | G15: 2C用户本人提纲：按生活背景—经历—选择—方案的顺序呈现。保留研究任务，按对象区分问法；同义主问合并，细节保留为按条件追问。 原编号题：8条；在“原题映射”按本题编号检索。 | H15: 同意
A16: Q-M4.3-02 | B16: C4 续航与补能时间底线 按需选择 FGD：可用 IHV：可用 | C16: 连接行程、停车窗口和可用续航，提供技术取舍需求输入；不直接决定电气架构。 | D16: 车主：您充电时一定要充满吗？一般会充到多少，例如80%、90%或100%？为什么？ 意向者：您充电时一定要充满吗？一般会充到多少，例如80%、90%或100%？为什么？ | E16: 1. 起止电量与下一次任务 2. 家充与途中补能分开 3. 可接受等待底线 | F16: 按研究目的选用；有实际经历先谈经历，设想单独记录。 原追问4条：在“原追问审阅”按题卡编号筛选；详情保留在该表，不能把全部追问逐项念出。 | G16: 按审阅意见改为具体充电上限习惯。 原编号题：3条；在“原题映射”按本题编号检索。 | H16: 已按意见修改 | I16: 你充电一定要冲到满吗？一般情况下冲到多少？90% 100%。。。这样问比较好，改一下
A17: Q-M4.3-03 | B17: C4 续航与补能时间底线 按需选择 FGD：可用 IHV：可用 | C17: 连接行程、停车窗口和可用续航，提供技术取舍需求输入；不直接决定电气架构。 | D17: 车主：对您来说，车辆实际续航至少达到多少才可以接受？低于多少会让您放弃购买？ 意向者：对您来说，车辆实际续航至少达到多少才可以接受？低于多少会让您放弃购买？ | E17: 1. 先说明实际差异 2. 选择理由与改变选择的临界点 3. 价格和续航取自本项目材料 | F17: 按研究目的选用；有实际经历先谈经历，设想单独记录。 需准备并核验：续航价格组合；缺材料时暂不执行方案评价。 原追问2条：在“原追问审阅”按题卡编号筛选；详情保留在该表，不能把全部追问逐项念出。 | G17: 按审阅意见改为可回答的续航底线。 原编号题：3条；在“原题映射”按本题编号检索。 | H17: 已按意见修改 | I17: 看不懂；我觉得可以问续航多少是底线之类的
A18: Q-M4.4-01 | B18: C4 智驾信任及使用边界 核心信息 FGD：可用 IHV：可用 | C18: 识别辅助驾驶任务、信任与接管边界，不将功能偏好当安全验证。 | D18: 车主：您了解或使用过哪些驾驶辅助功能？请分别说明。 意向者：您了解或体验过哪些驾驶辅助功能？哪些已经实际使用，哪些只是听说？ | E18: 1. 了解、试用、日常使用区分 2. 最近一次场景 3. 不用或关闭的原因 | F18: 按研究目的选用；有实际经历先谈经历，设想单独记录。 原追问6条：在“原追问审阅”按题卡编号筛选；详情保留在该表，不能把全部追问逐项念出。 | G18: 2C用户本人提纲：按生活背景—经历—选择—方案的顺序呈现。保留研究任务，按对象区分问法；同义主问合并，细节保留为按条件追问。 原编号题：7条；在“原题映射”按本题编号检索。 | H18: 同意
A19: Q-M4.4-02 | B19: C4 智驾信任及使用边界 按需选择 FGD：可用 IHV：可用 | C19: 识别辅助驾驶任务、信任与接管边界，不将功能偏好当安全验证。 | D19: 车主：哪些驾驶辅助任务最值得帮助您完成，哪些没有必要？ 意向者：哪些驾驶辅助任务最值得帮助您完成，哪些没有必要？ | E19: 1. 驾驶者与乘员分别回答 2. 频次、困难、信任及接管边界 3. 不将功能描述为自动驾驶 | F19: 按研究目的选用；有实际经历先谈经历，设想单独记录。 原追问5条：在“原追问审阅”按题卡编号筛选；详情保留在该表，不能把全部追问逐项念出。 | G19: 2C用户本人提纲：按生活背景—经历—选择—方案的顺序呈现。保留研究任务，按对象区分问法；同义主问合并，细节保留为按条件追问。 原编号题：6条；在“原题映射”按本题编号检索。 | H19: 同意
A20: Q-M4.4-03 | B20: C4 智驾信任及使用边界 按需选择 FGD：可用 IHV：可用 | C20: 识别辅助驾驶任务、信任与接管边界，不将功能偏好当安全验证。 | D20: 车主：什么条件下您愿意使用辅助驾驶，什么条件下会停止使用？ 意向者：什么条件下您愿意使用辅助驾驶，什么条件下会停止使用？ | E20: 1. 理解的责任边界 2. 失误和接管经历 3. 想象担忧与真实事件分开 | F20: 按研究目的选用；有实际经历先谈经历，设想单独记录。 原追问0条：在“原追问审阅”按题卡编号筛选；详情保留在该表，不能把全部追问逐项念出。 | G20: 2C用户本人提纲：按生活背景—经历—选择—方案的顺序呈现。保留研究任务，按对象区分问法；同义主问合并，细节保留为按条件追问。 原编号题：0条；在“原题映射”按本题编号检索。 本次补充的新题。 | H20: 同意
A21: Q-M4.4-04 | B21: C4 智驾信任及使用边界 按需选择 FGD：可用 IHV：可用 | C21: 识别辅助驾驶任务、信任与接管边界，不将功能偏好当安全验证。 | D21: 车主：对自动泊车，您最希望它解决什么问题？ 意向者：对自动泊车，您最希望它解决什么问题？ | E21: 1. 车位和场景 2. 速度、准确性、接管 3. 若评估付费须提供明确功能材料 | F21: 按研究目的选用；有实际经历先谈经历，设想单独记录。 原追问0条：在“原追问审阅”按题卡编号筛选；详情保留在该表，不能把全部追问逐项念出。 | G21: 2C用户本人提纲：按生活背景—经历—选择—方案的顺序呈现。保留研究任务，按对象区分问法；同义主问合并，细节保留为按条件追问。 原编号题：3条；在“原题映射”按本题编号检索。 | H21: 同意
A22: Q-M4.5-01 | B22: C4 安全与耐久期待 核心信息 FGD：可用 IHV：可用 | C22: 理解安全、健康与耐久认知和证据需求；不替代工程、医学或法规验证。 | D22: 车主：您在出行或选车时最关注什么安全问题？ 意向者：您在出行或选车时最关注什么安全问题？ | E22: 1. 影响哪位乘员、何种情境 2. 判断依据 3. 碰撞评级与功能的理解分别确认 | F22: 按研究目的选用；有实际经历先谈经历，设想单独记录。 原追问7条：在“原追问审阅”按题卡编号筛选；详情保留在该表，不能把全部追问逐项念出。 | G22: 2C用户本人提纲：按生活背景—经历—选择—方案的顺序呈现。保留研究任务，按对象区分问法；同义主问合并，细节保留为按条件追问。 原编号题：5条；在“原题映射”按本题编号检索。 | H22: 同意
A23: Q-M4.5-02 | B23: C4 安全与耐久期待 按需选择 FGD：可用 IHV：可用 | C23: 理解安全、健康与耐久认知和证据需求；不替代工程、医学或法规验证。 | D23: 车主：您怎样理解车内健康？哪些实际经历让您在意？ 意向者：您怎样理解车内健康？哪些实际经历让您在意？ | E23: 1. 空气、气味、材质或其他自发提及因素 2. 判断证据 3. 不要将偏好当医学结论 | F23: 按研究目的选用；有实际经历先谈经历，设想单独记录。 原追问9条：在“原追问审阅”按题卡编号筛选；详情保留在该表，不能把全部追问逐项念出。 | G23: 2C用户本人提纲：按生活背景—经历—选择—方案的顺序呈现。保留研究任务，按对象区分问法；同义主问合并，细节保留为按条件追问。 原编号题：9条；在“原题映射”按本题编号检索。 | H23: 同意
A24: Q-M4.5-03 | B24: C4 安全与耐久期待 按需选择 FGD：可用 IHV：可用 | C24: 理解安全、健康与耐久认知和证据需求；不替代工程、医学或法规验证。 | D24: 车主：您对电池保护、耐久或质保有什么了解和顾虑？ 意向者：您对电池保护、耐久或质保有什么了解和顾虑？ | E24: 1. 实际经历与宣传名词区分 2. 谁影响认知 3. 更需要什么证据或承诺 | F24: 按研究目的选用；有实际经历先谈经历，设想单独记录。 原追问0条：在“原追问审阅”按题卡编号筛选；详情保留在该表，不能把全部追问逐项念出。 | G24: 2C用户本人提纲：按生活背景—经历—选择—方案的顺序呈现。保留研究任务，按对象区分问法；同义主问合并，细节保留为按条件追问。 原编号题：2条；在“原题映射”按本题编号检索。 | H24: 同意
A25: Q-M4.5-04 | B25: C4 安全与耐久期待 按需选择 FGD：可用 IHV：可用 | C25: 理解安全、健康与耐久认知和证据需求；不替代工程、医学或法规验证。 | D25: 车主：车底或底盘通过性是否影响过您的出行或购车考虑？ 意向者：车底或底盘通过性是否影响过您的出行或购车考虑？ | E25: 1. 具体路段与是否发生磕碰 2. 实际损失与担忧区分 3. 电池相关追问仅适用车型 | F25: 按研究目的选用；有实际经历先谈经历，设想单独记录。 原追问1条：在“原追问审阅”按题卡编号筛选；详情保留在该表，不能把全部追问逐项念出。 | G25: 2C用户本人提纲：按生活背景—经历—选择—方案的顺序呈现。保留研究任务，按对象区分问法；同义主问合并，细节保留为按条件追问。 原编号题：4条；在“原题映射”按本题编号检索。 | H25: 同意

Sheet 2C-05 产品与配置
A2: 2C-05 产品与配置
A3: 32张题卡。2C：消费者本人及家庭的真实经历。黄色列供你填写；核心信息已回答就不重复问。
A5: 题卡编号 | B5: 子模块与适用方法 | C5: 研究目的与边界 | D5: 主问：按对象选用 | E5: 核心追问：覆盖信息 | F5: 触发条件与观察任务 | G5: 归并调整与来源 | H5: 确认状态 | I5: 你的修改意见
A6: Q-M5.1-01 | B6: C5 整体概念评价 核心信息 FGD：可用 IHV：可用 | C6: 检验概念理解、场景匹配与竞争差异。 | D6: 车主：看完这份产品概念，您的第一反应是什么？ 意向者：看完这份产品概念，您的第一反应是什么？ | E6: 1. 先独立回答 2. 理解成什么车、适合谁 3. 最吸引与最疑惑 4. 不给“全面领先”的暗示 | F6: 仅当项目已准备并展示完整产品概念材料后触发；未展示产品概念时整题不出现。 原追问0条：在“原追问审阅”按题卡编号筛选；详情保留在该表，不能把全部追问逐项念出。 | G6: 按审阅意见增加产品概念材料触发门槛。 原编号题：2条；在“原题映射”按本题编号检索。 | H6: 已按意见修改 | I6: 需要有产品概念才会这题，如果没有的话这题不出现，那么需要在哪里有trigger
A7: Q-M5.1-02 | B7: C5 整体概念评价 按需选择 FGD：可用 IHV：可用 | C7: 检验概念理解、场景匹配与竞争差异。 | D7: 车主：请把这个概念放到您刚才讲的关键场景中，哪些合适，哪些不合适？ 意向者：请把这个概念放到您刚才讲的关键场景中，哪些合适，哪些不合适？ | E7: 1. 场景前提 2. 替代现有方案的条件 3. 没覆盖的人或任务 | F7: 仅当项目已准备并展示完整产品概念材料后触发；未展示产品概念时整题不出现。 原追问0条：在“原追问审阅”按题卡编号筛选；详情保留在该表，不能把全部追问逐项念出。 | G7: 按审阅意见增加产品概念材料触发门槛。 原编号题：1条；在“原题映射”按本题编号检索。 | H7: 已按意见修改 | I7: 需要有产品概念才会这题，如果没有的话这题不出现，那么需要在哪里有trigger
A8: Q-M5.1-03 | B8: C5 整体概念评价 按需选择 FGD：可用 IHV：可用 | C8: 检验概念理解、场景匹配与竞争差异。 | D8: 车主：看完产品概念后，哪些内容最吸引您？哪些地方仍不清楚或需要改进？ 意向者：看完产品概念后，哪些内容最吸引您？哪些地方仍不清楚或需要改进？ | E8: 1. 对比依据一致 2. 不熟悉的竞品可跳过 3. 产品判断与品牌判断分开 | F8: 仅当项目已展示完整产品概念材料后触发；不再假设存在未展示的备选方案。 原追问0条：在“原追问审阅”按题卡编号筛选；详情保留在该表，不能把全部追问逐项念出。 | G8: 按审阅意见删除不存在的“备选方案”前提。 原编号题：2条；在“原题映射”按本题编号检索。 | H8: 已按意见修改 | I8: 备选方案？这个没有出现过，所以问题不对
A9: Q-M5.2-01 | B9: C5 外观轮廓、前脸与车尾 核心信息 FGD：可用 IHV：可用 | C9: 比较具体外观方案的偏好、排斥与取舍；各部位材料分开记录。 | D9: 车主：请比较这些整体车型轮廓方案，分别说说吸引和排斥您的地方，再选最适合的一款。 意向者：请比较这些整体车型轮廓方案，分别说说吸引和排斥您的地方，再选最适合的一款。 | E9: 1. 比例、形面和用途联想 2. 辨识度与前瞻感分别追问 3. 材料逐款编号 | F9: 按研究目的选用；有实际经历先谈经历，设想单独记录。 需准备并核验：外观方案图；缺材料时暂不执行方案评价。 观察/活动：按已记录的材料顺序逐一展示；先个人评价再相互比较，前脸和车尾独立记录。 原追问6条：在“原追问审阅”按题卡编号筛选；详情保留在该表，不能把全部追问逐项念出。 | G9: 按审阅意见将“体态”改为“车型轮廓”。 原编号题：4条；在“原题映射”按本题编号检索。 | H9: 已按意见修改 | I9: 体态不是这么说的，应该叫：车型轮廓
A10: Q-M5.2-02 | B10: C5 外观体态、前脸与车尾 按需选择 FGD：可用 IHV：可用 | C10: 比较具体外观方案的偏好、排斥与取舍；各部位材料分开记录。 | D10: 车主：请比较这些前脸方案，哪款更适合您的用车场景？ 意向者：请比较这些前脸方案，哪款更适合您的用车场景？ | E10: 1. 格栅、灯光与细节 2. 辨识度和耐看程度 3. 不把“大格栅”预设为高级 | F10: 按研究目的选用；有实际经历先谈经历，设想单独记录。 需准备并核验：外观方案图；缺材料时暂不执行方案评价。 原追问8条：在“原追问审阅”按题卡编号筛选；详情保留在该表，不能把全部追问逐项念出。 | G10: 2C用户本人提纲：按生活背景—经历—选择—方案的顺序呈现。实际经历与方案评价分开；按材料逐项评价，保留排斥理由和取舍，不把喜欢等同购买。 原编号题：6条；在“原题映射”按本题编号检索。 | H10: 同意
A11: Q-M5.2-03 | B11: C5 外观体态、前脸与车尾 按需选择 FGD：可用 IHV：可用 | C11: 比较具体外观方案的偏好、排斥与取舍；各部位材料分开记录。 | D11: 车主：请比较这些车尾方案，哪款更适合您？ 意向者：请比较这些车尾方案，哪款更适合您？ | E11: 1. 具体喜欢与不喜欢 2. 辨识度、功能联想 3. 车尾材料与前脸材料ID分开 | F11: 按研究目的选用；有实际经历先谈经历，设想单独记录。 需准备并核验：外观方案图；缺材料时暂不执行方案评价。 原追问8条：在“原追问审阅”按题卡编号筛选；详情保留在该表，不能把全部追问逐项念出。 | G11: 2C用户本人提纲：按生活背景—经历—选择—方案的顺序呈现。实际经历与方案评价分开；按材料逐项评价，保留排斥理由和取舍，不把喜欢等同购买。 原编号题：6条；在“原题映射”按本题编号检索。 | H11: 同意
A12: Q-M5.2-04 | B12: C5 外观体态、前脸与车尾 按需选择 FGD：可用 IHV：可用 | C12: 比较具体外观方案的偏好、排斥与取舍；各部位材料分开记录。 | D12: 车主：从车型轮廓、前脸和车尾来看，哪一部分最符合您的期待？哪一部分最需要调整？ 意向者：从车型轮廓、前脸和车尾来看，哪一部分最符合您的期待？哪一部分最需要调整？ | E12: 1. 造型与空间、价格、品牌等冲突 2. 先问过去真实取舍，再谈假设 | F12: 按研究目的选用；有实际经历先谈经历，设想单独记录。 原追问7条：在“原追问审阅”按题卡编号筛选；详情保留在该表，不能把全部追问逐项念出。 | G12: 按审阅意见改为清楚的整体外观评价。 原编号题：3条；在“原题映射”按本题编号检索。 | H12: 已按意见修改 | I12: 看不懂？这个题目很奇怪
A13: Q-M5.3-01 | B13: C5 内饰与CMF 核心信息 FGD：可用 IHV：可用 | C13: 识别内饰风格、色彩、材料与工艺的接受条件。 | D13: 车主：如果用几个形容词描述这套内饰，您会怎么说？为什么？ 意向者：如果用几个形容词描述这套内饰，您会怎么说？为什么？ | E13: 1. 偏好与排斥 2. 新颖和辨识度分别记录 3. 家庭/商务氛围不强迫二选一 | F13: 按研究目的选用；有实际经历先谈经历，设想单独记录。 需准备并核验：颜色/材料/工艺样板；缺材料时暂不执行方案评价。 原追问8条：在“原追问审阅”按题卡编号筛选；详情保留在该表，不能把全部追问逐项念出。 | G13: 按审阅意见采用形容词引导。 原编号题：8条；在“原题映射”按本题编号检索。 | H13: 已按意见修改 | I13: 用形容词来形容，你会怎么说
A14: Q-M5.3-02 | B14: C5 内饰与CMF 按需选择 FGD：可用 IHV：可用 | C14: 识别内饰风格、色彩、材料与工艺的接受条件。 | D14: 车主：请看这些颜色、材质与工艺方案，哪些适合您，哪些不能接受？ 意向者：请看这些颜色、材质与工艺方案，哪些适合您，哪些不能接受？ | E14: 1. 触感、清洁、耐用与品质判断 2. 实际样材与屏幕图像区别 3. 商务礼仪只在相关时追问 | F14: 按研究目的选用；有实际经历先谈经历，设想单独记录。 需准备并核验：颜色/材料/工艺样板；缺材料时暂不执行方案评价。 原追问4条：在“原追问审阅”按题卡编号筛选；详情保留在该表，不能把全部追问逐项念出。 | G14: 2C用户本人提纲：按生活背景—经历—选择—方案的顺序呈现。实际经历与方案评价分开；按材料逐项评价，保留排斥理由和取舍，不把喜欢等同购买。 原编号题：3条；在“原题映射”按本题编号检索。 | H14: 同意
A15: Q-M5.3-03 | B15: C5 内饰与CMF 按需选择 FGD：可用 IHV：可用 | C15: 识别内饰风格、色彩、材料与工艺的接受条件。 | D15: 车主：车身与内饰颜色，您分别偏好哪些、排斥哪些？ 意向者：车身与内饰颜色，您分别偏好哪些、排斥哪些？ | E15: 1. 实际选择经历 2. 原因 3. 吸热或文化禁忌以本人理解记录，不写成市场事实 | F15: 按研究目的选用；有实际经历先谈经历，设想单独记录。 需准备并核验：颜色/材料/工艺样板；缺材料时暂不执行方案评价。 原追问3条：在“原追问审阅”按题卡编号筛选；详情保留在该表，不能把全部追问逐项念出。 | G15: 2C用户本人提纲：按生活背景—经历—选择—方案的顺序呈现。实际经历与方案评价分开；按材料逐项评价，保留排斥理由和取舍，不把喜欢等同购买。 原编号题：7条；在“原题映射”按本题编号检索。 | H15: 同意
A16: Q-M5.4-01 | B16: C5 座椅空间与进出动线 按需选择 FGD：可用 IHV：可用 | C16: 在明确材料或实车下检验空间布局、动线和功能取舍。 | D16: 车主：按材料中的实际长宽高，把这辆车放到您常走的路线和停车地点，会遇到什么？ 意向者：按材料中的实际长宽高，把这辆车放到您常走的路线和停车地点，会遇到什么？ | E16: 1. 能否停入、转弯、开门与限高 2. 尺寸是否构成否决 3. 不由级别推算车长 | F16: 按研究目的选用；有实际经历先谈经历，设想单独记录。 需准备并核验：尺寸及座椅空间方案；缺材料时暂不执行方案评价。 原追问4条：在“原追问审阅”按题卡编号筛选；详情保留在该表，不能把全部追问逐项念出。 | G16: 2C用户本人提纲：按生活背景—经历—选择—方案的顺序呈现。实际经历与方案评价分开；按材料逐项评价，保留排斥理由和取舍，不把喜欢等同购买。 原编号题：6条；在“原题映射”按本题编号检索。 | H16: 同意
A17: Q-M5.4-02 | B17: C5 座椅空间与进出动线 核心信息 FGD：可用 IHV：可用 | C17: 在明确材料或实车下检验空间布局、动线和功能取舍。 | D17: 车主：这些座椅布局中，哪种最能完成您的日常和关键任务？ 意向者：这些座椅布局中，哪种最能完成您的日常和关键任务？ | E17: 1. 人数、座位角色、儿童座椅、行李 2. 四/六/七座仅在材料存在时比较 | F17: 按研究目的选用；有实际经历先谈经历，设想单独记录。 需准备并核验：尺寸及座椅空间方案；缺材料时暂不执行方案评价。 原追问5条：在“原追问审阅”按题卡编号筛选；详情保留在该表，不能把全部追问逐项念出。 | G17: 2C用户本人提纲：按生活背景—经历—选择—方案的顺序呈现。实际经历与方案评价分开；按材料逐项评价，保留排斥理由和取舍，不把喜欢等同购买。 原编号题：4条；在“原题映射”按本题编号检索。 | H17: 同意
A18: Q-M5.4-03 | B18: C5 座椅空间与进出动线 按需选择 FGD：可用 IHV：可用 | C18: 在明确材料或实车下检验空间布局、动线和功能取舍。 | D18: 车主：请比较这些后排进出方式，哪种更适合经常使用的人？ 意向者：请比较这些后排进出方式，哪种更适合经常使用的人？ | E18: 1. 过道、前移座椅、台阶和门开口 2. 操作步骤 3. 有样车才做实操 | F18: 按研究目的选用；有实际经历先谈经历，设想单独记录。 需准备并核验：尺寸及座椅空间方案；缺材料时暂不执行方案评价。 原追问2条：在“原追问审阅”按题卡编号筛选；详情保留在该表，不能把全部追问逐项念出。 | G18: 2C用户本人提纲：按生活背景—经历—选择—方案的顺序呈现。实际经历与方案评价分开；按材料逐项评价，保留排斥理由和取舍，不把喜欢等同购买。 原编号题：2条；在“原题映射”按本题编号检索。 | H18: 同意
A19: Q-M5.4-04 | B19: C5 座椅空间与进出动线 按需选择 FGD：可用 IHV：可用 | C19: 在明确材料或实车下检验空间布局、动线和功能取舍。 | D19: 车主：这些座椅和储物空间变化方式分别会在什么情境下使用？ 意向者：这些座椅和储物空间变化方式分别会在什么情境下使用？ | E19: 1. 实际物品或事件 2. 操作负担 3. 喜欢但不用与真正需要分开 | F19: 按研究目的选用；有实际经历先谈经历，设想单独记录。 需准备并核验：尺寸及座椅空间方案；缺材料时暂不执行方案评价。 原追问8条：在“原追问审阅”按题卡编号筛选；详情保留在该表，不能把全部追问逐项念出。 | G19: 2C用户本人提纲：按生活背景—经历—选择—方案的顺序呈现。实际经历与方案评价分开；按材料逐项评价，保留排斥理由和取舍，不把喜欢等同购买。 原编号题：7条；在“原题映射”按本题编号检索。 | H19: 同意
A20: Q-M5.4-05 | B20: C5 座椅空间与进出动线 按需选择 FGD：可用 IHV：可用 | C20: 在明确材料或实车下检验空间布局、动线和功能取舍。 | D20: 车主：这款尾门设计会怎样影响您的装载、取物或停靠？ 意向者：这款尾门设计会怎样影响您的装载、取物或停靠？ | E20: 1. 最深处物品、站位、后方空间 2. 坐立承重仅以核验材料为准 | F20: 按研究目的选用；有实际经历先谈经历，设想单独记录。 需准备并核验：尺寸及座椅空间方案；缺材料时暂不执行方案评价。 原追问6条：在“原追问审阅”按题卡编号筛选；详情保留在该表，不能把全部追问逐项念出。 | G20: 2C用户本人提纲：按生活背景—经历—选择—方案的顺序呈现。实际经历与方案评价分开；按材料逐项评价，保留排斥理由和取舍，不把喜欢等同购买。 原编号题：4条；在“原题映射”按本题编号检索。 | H20: 同意
A21: Q-M5.4-06 | B21: C5 座椅空间与进出动线 按需选择 FGD：可用 IHV：可用 | C21: 在明确材料或实车下检验空间布局、动线和功能取舍。 | D21: 车主：这组车门、导轨及侧窗方案，会怎样影响进出、视野或使用？ 意向者：这组车门、导轨及侧窗方案，会怎样影响进出、视野或使用？ | E21: 1. 第三排采光与视线 2. 喜欢/排斥原因 3. 外观与使用分别记录 | F21: 按研究目的选用；有实际经历先谈经历，设想单独记录。 需准备并核验：尺寸及座椅空间方案；缺材料时暂不执行方案评价。 原追问1条：在“原追问审阅”按题卡编号筛选；详情保留在该表，不能把全部追问逐项念出。 | G21: 2C用户本人提纲：按生活背景—经历—选择—方案的顺序呈现。实际经历与方案评价分开；按材料逐项评价，保留排斥理由和取舍，不把喜欢等同购买。 原编号题：1条；在“原题映射”按本题编号检索。 | H21: 同意
A22: Q-M5.4-07 | B22: C5 座椅空间与进出动线 按需选择 FGD：可用 IHV：可用 | C22: 在明确材料或实车下检验空间布局、动线和功能取舍。 | D22: 车主：这些车顶方案中，您倾向哪种？ 意向者：这些车顶方案中，您倾向哪种？ | E22: 1. 采光、遮阳、视野、空间和维护 2. 加装后总高度及停车限制 | F22: 按研究目的选用；有实际经历先谈经历，设想单独记录。 需准备并核验：尺寸及座椅空间方案；缺材料时暂不执行方案评价。 【项目包含车顶附件】加装后的总高度如何影响常用停车点？数值以已审核尺寸卡为准。 原追问7条：在“原追问审阅”按题卡编号筛选；详情保留在该表，不能把全部追问逐项念出。 | G22: 2C用户本人提纲：按生活背景—经历—选择—方案的顺序呈现。实际经历与方案评价分开；按材料逐项评价，保留排斥理由和取舍，不把喜欢等同购买。 原编号题：2条；在“原题映射”按本题编号检索。 | H22: 同意
A23: Q-M5.4-08 | B23: C5 座椅空间与进出动线 按需选择 FGD：可用 IHV：可用 | C23: 在明确材料或实车下检验空间布局、动线和功能取舍。 | D23: 车主：增加中央岛台等功能会改变车内通道，您怎样权衡？ 意向者：增加中央岛台等功能会改变车内通道，您怎样权衡？ | E23: 1. 谁会使用、频次、上下车 2. 功能价值与通道成本 3. 不预设“尊享” | F23: 按研究目的选用；有实际经历先谈经历，设想单独记录。 需准备并核验：尺寸及座椅空间方案；缺材料时暂不执行方案评价。 原追问3条：在“原追问审阅”按题卡编号筛选；详情保留在该表，不能把全部追问逐项念出。 | G23: 2C用户本人提纲：按生活背景—经历—选择—方案的顺序呈现。实际经历与方案评价分开；按材料逐项评价，保留排斥理由和取舍，不把喜欢等同购买。 原编号题：1条；在“原题映射”按本题编号检索。 | H23: 同意
A24: Q-M5.5-01 | B24: C5 座舱交互方案 核心信息 FGD：可用 IHV：可用 | C24: 比较交互方案与乘员任务的匹配，不以静态演示推断行驶安全。 | D24: 车主：比较这些屏幕布局，哪些更适合不同乘员的任务？ 意向者：比较这些屏幕布局，哪些更适合不同乘员的任务？ | E24: 1. 驾驶员、副驾、后排用途 2. 干扰或闲置 3. 不预设副驾娱乐“不专业” | F24: 按研究目的选用；有实际经历先谈经历，设想单独记录。 需准备并核验：交互原型及限制说明；缺材料时暂不执行方案评价。 原追问7条：在“原追问审阅”按题卡编号筛选；详情保留在该表，不能把全部追问逐项念出。 | G24: 2C用户本人提纲：按生活背景—经历—选择—方案的顺序呈现。实际经历与方案评价分开；按材料逐项评价，保留排斥理由和取舍，不把喜欢等同购买。 原编号题：4条；在“原题映射”按本题编号检索。 | H24: 同意
A25: Q-M5.5-02 | B25: C5 座舱交互方案 按需选择 FGD：可用 IHV：可用 | C25: 比较交互方案与乘员任务的匹配，不以静态演示推断行驶安全。 | D25: 车主：在这些按键与触控方案中，您希望哪些操作采用哪种方式？ 意向者：在这些按键与触控方案中，您希望哪些操作采用哪种方式？ | E25: 1. 驾驶与停车时区分 2. 常用操作、盲操和误触 3. 静止演示不等于行驶安全验证 | F25: 按研究目的选用；有实际经历先谈经历，设想单独记录。 需准备并核验：交互原型及限制说明；缺材料时暂不执行方案评价。 原追问0条：在“原追问审阅”按题卡编号筛选；详情保留在该表，不能把全部追问逐项念出。 | G25: 2C用户本人提纲：按生活背景—经历—选择—方案的顺序呈现。实际经历与方案评价分开；按材料逐项评价，保留排斥理由和取舍，不把喜欢等同购买。 原编号题：3条；在“原题映射”按本题编号检索。 | H25: 同意
... A36: Q-M5.7-04 | B36: C5 强制取舍与必选项 按需选择 FGD：可用 IHV：可用 | C36: 在清晰功能与预算约束下识别配置优先级；法规底线不进入删减交易。 | D36: 车主：有没有重要需求或功能是今天没有覆盖到的？ 意向者：有没有重要需求或功能是今天没有覆盖到的？ | E36: 1. 具体场景、现有解决方式 2. 与刚才保留项相比优先级 3. 不重复整套提问 | F36: 按研究目的选用；有实际经历先谈经历，设想单独记录。 原追问1条：在“原追问审阅”按题卡编号筛选；详情保留在该表，不能把全部追问逐项念出。 | G36: 2C用户本人提纲：按生活背景—经历—选择—方案的顺序呈现。实际经历与方案评价分开；按材料逐项评价，保留排斥理由和取舍，不把喜欢等同购买。 原编号题：1条；在“原题映射”按本题编号检索。 | H36: 同意
A37: Q-M5.6-07 | B37: C5 功能与配置组合 按需选择 FGD：可用 IHV：可用 | C37: 检验具体功能是否对应真实任务及使用条件，区分喜欢与需要。 | D37: 车主：在炎热或强日照环境下，车辆隔热和空调降温表现需要达到什么程度？ 意向者：在炎热或强日照环境下，车辆隔热和空调降温表现需要达到什么程度？ | E37: 1. 分别确认隔热玻璃、遮阳帘、座椅通风的作用 2. 先独立评价再排序，允许都不需要 3. 对应暴晒、行驶、前后排的具体需求 | F37: 按研究目的选用；有实际经历先谈经历，设想单独记录。 需准备并核验：热舒适配置说明；缺材料时暂不执行方案评价。 原追问2条：在“原追问审阅”按题卡编号筛选；详情保留在该表，不能把全部追问逐项念出。 | G37: 按审阅意见把“热舒适”改为隔热与空调降温。 原编号题：4条；在“原题映射”按本题编号检索。 | H37: 已按意见修改 | I37: 热舒适？这么说吗？这里是隔热吧，

Sheet 2C-06 品牌与购买条件
A2: 2C-06 品牌与购买条件
A3: 15张题卡。2C：消费者本人及家庭的真实经历。黄色列供你填写；核心信息已回答就不重复问。
A5: 题卡编号 | B5: 子模块与适用方法 | C5: 研究目的与边界 | D5: 主问：按对象选用 | E5: 核心追问：覆盖信息 | F5: 触发条件与观察任务 | G5: 归并调整与来源 | H5: 确认状态 | I5: 你的修改意见
A6: Q-M6.1-01 | B6: C6 自发品牌认知 核心信息 FGD：可用 IHV：可用 | C6: 区分品牌自发认知、提示认知及亲身体验，为品牌沟通提供依据。 | D6: 车主：不看品牌提示，您首先想到哪些相关汽车品牌？分别有什么印象？ 意向者：不看品牌提示，您首先想到哪些相关汽车品牌？分别有什么印象？ | E6: 1. 熟悉、了解与亲身体验区分 2. 自发再提示 3. 品牌印象不当市场事实 | F6: 按研究目的选用；有实际经历先谈经历，设想单独记录。 原追问7条：在“原追问审阅”按题卡编号筛选；详情保留在该表，不能把全部追问逐项念出。 | G6: 2C用户本人提纲：按生活背景—经历—选择—方案的顺序呈现。保留研究任务，按对象区分问法；同义主问合并，细节保留为按条件追问。 原编号题：2条；在“原题映射”按本题编号检索。 | H6: 同意
A7: Q-M6.1-02 | B7: C6 自发品牌认知 按需选择 FGD：可用 IHV：可用 | C7: 区分品牌自发认知、提示认知及亲身体验，为品牌沟通提供依据。 | D7: 车主：对您熟悉的品牌，您如何描述它们之间的差异？ 意向者：对您熟悉的品牌，您如何描述它们之间的差异？ | E7: 1. 功能、可靠性、身份、服务等由受访者自发提出 2. 避免“鄙视链”诱导 | F7: 按研究目的选用；有实际经历先谈经历，设想单独记录。 原追问13条：在“原追问审阅”按题卡编号筛选；详情保留在该表，不能把全部追问逐项念出。 | G7: 2C用户本人提纲：按生活背景—经历—选择—方案的顺序呈现。保留研究任务，按对象区分问法；同义主问合并，细节保留为按条件追问。 原编号题：12条；在“原题映射”按本题编号检索。 | H7: 同意
A8: Q-M6.1-03 | B8: C6 自发品牌认知 按需选择 FGD：可用 IHV：可用 | C8: 区分品牌自发认知、提示认知及亲身体验，为品牌沟通提供依据。 | D8: 车主：您信任或不信任某个品牌，主要依据什么？ 意向者：您信任或不信任某个品牌，主要依据什么？ | E8: 1. 经历、他人、信息来源 2. 哪些证据能改变判断 3. 中国品牌仅在项目目标相关时提示 | F8: 按研究目的选用；有实际经历先谈经历，设想单独记录。 原追问4条：在“原追问审阅”按题卡编号筛选；详情保留在该表，不能把全部追问逐项念出。 | G8: 2C用户本人提纲：按生活背景—经历—选择—方案的顺序呈现。保留研究任务，按对象区分问法；同义主问合并，细节保留为按条件追问。 原编号题：7条；在“原题映射”按本题编号检索。 | H8: 同意
A9: Q-M6.2-01 | B9: C6 品牌揭示后的评价变化 核心信息 FGD：可用 IHV：可用 | C9: 比较品牌揭示前后评价，识别品牌对产品判断的影响。 | D9: 车主：现在告诉您这份概念的品牌，您刚才的判断发生了什么变化？ 意向者：现在告诉您这份概念的品牌，您刚才的判断发生了什么变化？ | E9: 1. 明确记录揭示前后 2. 变好、变差或不变都可 3. 为什么 | F9: 按研究目的选用；有实际经历先谈经历，设想单独记录。 需准备并核验：品牌揭示材料；缺材料时暂不执行方案评价。 观察/活动：保存揭示前评价，再展示品牌并记录变化；不得用主持人口头评价暗示品牌水平。 原追问0条：在“原追问审阅”按题卡编号筛选；详情保留在该表，不能把全部追问逐项念出。 | G9: 2C用户本人提纲：按生活背景—经历—选择—方案的顺序呈现。保留研究任务，按对象区分问法；同义主问合并，细节保留为按条件追问。 原编号题：1条；在“原题映射”按本题编号检索。 | H9: 同意
A10: Q-M6.2-02 | B10: C6 品牌揭示后的评价变化 按需选择 FGD：可用 IHV：可用 | C10: 比较品牌揭示前后评价，识别品牌对产品判断的影响。 | D10: 车主：如果在您的家庭、工作或社交场景使用这个品牌，您有什么感受？ 意向者：如果在您的家庭、工作或社交场景使用这个品牌，您有什么感受？ | E10: 1. 请用具体人员和场合说明感受，允许没有影响 2. 如果同时存在公共服务或其他用途版本，仅在项目涉及且已展示核验材料时询问区隔需求 3. 不预设公共服务版本损害形象，不把用途关联当人群价值判断 | F10: 按研究目的选用；有实际经历先谈经历，设想单独记录。 需准备并核验：品牌揭示材料；缺材料时暂不执行方案评价。 【商务采购或接待】品牌是否需要满足客户、合作方或内部采购制度要求？请举例，不预设存在品牌层级。 原追问6条：在“原追问审阅”按题卡编号筛选；详情保留在该表，不能把全部追问逐项念出。 | G10: 2C用户本人提纲：按生活背景—经历—选择—方案的顺序呈现。保留研究任务，按对象区分问法；同义主问合并，细节保留为按条件追问。 原编号题：2条；在“原题映射”按本题编号检索。 | H10: 同意
A11: Q-M6.3-01 | B11: C6 价格与版型 核心信息 FGD：可用 IHV：可用 | C11: 理解报价、版型、月付及保障条款的接受理由；定性答案不推算市场最优价格。 | D11: 车主：在功能、版本和价格口径说明清楚后，您怎样看待这份报价？ 意向者：在功能、版本和价格口径说明清楚后，您怎样看待这份报价？ | E11: 1. 币种、落地/裸车、日期 2. 预算与比较对象 3. 不把回答解释为定量定价模型 | F11: 按研究目的选用；有实际经历先谈经历，设想单独记录。 需准备并核验：报价/版型/金融条款；缺材料时暂不执行方案评价。 原追问11条：在“原追问审阅”按题卡编号筛选；详情保留在该表，不能把全部追问逐项念出。 | G11: 2C用户本人提纲：按生活背景—经历—选择—方案的顺序呈现。保留研究任务，按对象区分问法；同义主问合并，细节保留为按条件追问。 原编号题：7条；在“原题映射”按本题编号检索。 | H11: 同意
A12: Q-M6.3-02 | B12: C6 价格与版型 按需选择 FGD：可用 IHV：可用 | C12: 理解报价、版型、月付及保障条款的接受理由；定性答案不推算市场最优价格。 | D12: 车主：这些版型之间的配置差异与价差，您会怎样选择？ 意向者：这些版型之间的配置差异与价差，您会怎样选择？ | E12: 1. 最低可接受版本 2. 升级原因 3. 放弃高配原因 4. 避免固定“30万港币”等旧项目数 | F12: 按研究目的选用；有实际经历先谈经历，设想单独记录。 需准备并核验：报价/版型/金融条款；缺材料时暂不执行方案评价。 原追问0条：在“原追问审阅”按题卡编号筛选；详情保留在该表，不能把全部追问逐项念出。 | G12: 2C用户本人提纲：按生活背景—经历—选择—方案的顺序呈现。保留研究任务，按对象区分问法；同义主问合并，细节保留为按条件追问。 原编号题：2条；在“原题映射”按本题编号检索。 | H12: 同意
A13: Q-M6.3-03 | B13: C6 价格与版型 按需选择 FGD：可用 IHV：可用 | C13: 理解报价、版型、月付及保障条款的接受理由；定性答案不推算市场最优价格。 | D13: 车主：在费用、期限、权益与退出条件清楚的情况下，您怎样看待这个月付方案？ 意向者：在费用、期限、权益与退出条件清楚的情况下，您怎样看待这个月付方案？ | E13: 1. 总支出与月付分别判断 2. 首付、尾款、保险和保养 3. 不把贷款与租赁混同 | F13: 按研究目的选用；有实际经历先谈经历，设想单独记录。 需准备并核验：报价/版型/金融条款；缺材料时暂不执行方案评价。 原追问2条：在“原追问审阅”按题卡编号筛选；详情保留在该表，不能把全部追问逐项念出。 | G13: 2C用户本人提纲：按生活背景—经历—选择—方案的顺序呈现。保留研究任务，按对象区分问法；同义主问合并，细节保留为按条件追问。 原编号题：2条；在“原题映射”按本题编号检索。 | H13: 同意
A14: Q-M6.3-04 | B14: C6 价格与版型 按需选择 FGD：可用 IHV：可用 | C14: 理解报价、版型、月付及保障条款的接受理由；定性答案不推算市场最优价格。 | D14: 车主：如果提供这份残值或回购保障，是否会改变您的考虑？ 意向者：如果提供这份残值或回购保障，是否会改变您的考虑？ | E14: 1. 具体比例、年限、车况和退出条款 2. 先自由顾虑后展示 3. 不默认60%/70%有效 | F14: 按研究目的选用；有实际经历先谈经历，设想单独记录。 需准备并核验：报价/版型/金融条款；缺材料时暂不执行方案评价。 原追问7条：在“原追问审阅”按题卡编号筛选；详情保留在该表，不能把全部追问逐项念出。 | G14: 2C用户本人提纲：按生活背景—经历—选择—方案的顺序呈现。保留研究任务，按对象区分问法；同义主问合并，细节保留为按条件追问。 原编号题：3条；在“原题映射”按本题编号检索。 | H14: 同意
A15: Q-M6.4-01 | B15: C6 购买顾虑与转化条件 核心信息 FGD：可用 IHV：可用 | C15: 识别购买考虑的剩余障碍与所需证据，意向不等于订单。 | D15: 车主：哪些条件满足后，您才会认真考虑购买目标车型？ 意向者：哪些条件满足后，您才会认真考虑购买目标车型？ | E15: 1. 当前主要障碍 2. 改善一个后是否仍有其他障碍 3. 购买意向与实际承诺分开 | F15: 按研究目的选用；有实际经历先谈经历，设想单独记录。 原追问3条：在“原追问审阅”按题卡编号筛选；详情保留在该表，不能把全部追问逐项念出。 | G15: 2C用户本人提纲：按生活背景—经历—选择—方案的顺序呈现。保留研究任务，按对象区分问法；同义主问合并，细节保留为按条件追问。 原编号题：7条；在“原题映射”按本题编号检索。 | H15: 同意
A16: Q-M6.4-02 | B16: C6 购买顾虑与转化条件 按需选择 FGD：可用 IHV：可用 | C16: 识别购买考虑的剩余障碍与所需证据，意向不等于订单。 | D16: 车主：在准备购买之前，您还需要确认什么？ 意向者：在准备购买之前，您还需要确认什么？ | E16: 1. 产品、品牌、服务、价格或使用条件 2. 向谁确认 3. 什么证据足够 | F16: 按研究目的选用；有实际经历先谈经历，设想单独记录。 原追问0条：在“原追问审阅”按题卡编号筛选；详情保留在该表，不能把全部追问逐项念出。 | G16: 2C用户本人提纲：按生活背景—经历—选择—方案的顺序呈现。保留研究任务，按对象区分问法；同义主问合并，细节保留为按条件追问。 原编号题：0条；在“原题映射”按本题编号检索。 本次补充的新题。 | H16: 同意
A17: Q-M6.4-03 | B17: C6 购买顾虑与转化条件 按需选择 FGD：可用 IHV：可用 | C17: 识别购买考虑的剩余障碍与所需证据，意向不等于订单。 | D17: 车主：对一个新进入市场的品牌，您需要看到什么才愿意考虑？ 意向者：对一个新进入市场的品牌，您需要看到什么才愿意考虑？ | E17: 1. 真实使用、服务承诺、口碑或试驾 2. 必须项与加分项 3. 不直接预设靠低价 | F17: 按研究目的选用；有实际经历先谈经历，设想单独记录。 原追问9条：在“原追问审阅”按题卡编号筛选；详情保留在该表，不能把全部追问逐项念出。 | G17: 2C用户本人提纲：按生活背景—经历—选择—方案的顺序呈现。保留研究任务，按对象区分问法；同义主问合并，细节保留为按条件追问。 原编号题：8条；在“原题映射”按本题编号检索。 | H17: 同意
... A20: Q-M6.5-03 | B20: C6 卖点表达理解 按需选择 FGD：可用 IHV：可用 | C20: 检验卖点理解、可信度和表达方式，不只收集喜欢程度。 | D20: 车主：如果向与您需求相近的人介绍这款产品，您会怎样用一句话说？ 意向者：如果向与您需求相近的人介绍这款产品，您会怎样用一句话说？ | E20: 1. 哪些词自然、哪些像广告 2. 是否准确反映已理解的产品 | F20: 按研究目的选用；有实际经历先谈经历，设想单独记录。 需准备并核验：卖点表达材料；缺材料时暂不执行方案评价。 原追问1条：在“原追问审阅”按题卡编号筛选；详情保留在该表，不能把全部追问逐项念出。 | G20: 2C用户本人提纲：按生活背景—经历—选择—方案的顺序呈现。保留研究任务，按对象区分问法；同义主问合并，细节保留为按条件追问。 原编号题：1条；在“原题映射”按本题编号检索。 | H20: 同意

Sheet 2B-00 执行话术
A2: 2B-00 执行话术
A3: 2张题卡。2B：渠道/专家的客户和市场证据。黄色列供你填写；核心信息已回答就不重复问。
A5: 题卡编号 | B5: 子模块与适用方法 | C5: 研究目的与边界 | D5: 主问：按对象选用 | E5: 核心追问：覆盖信息 | F5: 触发条件与观察任务 | G5: 归并调整与来源 | H5: 确认状态 | I5: 你的修改意见
A6: Q-E0-01 | B6: B0 客户/市场/专业证据 核心信息 经销商 媒体 主机厂专家 | C6: 明确参与许可、记录口径与结束核对，执行环节不计研究模块。 | D6: 经销商：今天我们想了解您在相关业务与市场中的经验。开始前先说明研究目的、记录方式和资料用途；您是否愿意参与？ 媒体：今天我们想了解您在相关业务与市场中的经验。开始前先说明研究目的、记录方式和资料用途；您是否愿意参与？ 主机厂专家：今天我们想了解您在相关业务与市场中的经验。开始前先说明研究目的、记录方式和资料用途；您是否愿意参与？ | E6: 1. 说明预计时长和资料用途；确认参与及录音等许可 2. 您可以不回答不方便分享的问题，商业数据可提供范围或说明未知 3. 职责与机构背景接下一模块，不在此重复介绍 | F6: 仅对熟悉该业务或有相关证据的经销商、媒体/主机厂专家询问；没有接触或数据可答未知。 原追问4条：在“原追问审阅”按题卡编号筛选；详情保留在该表，不能把全部追问逐项念出。 | G6: 2B渠道/专家提纲：本题回答对象是客户或市场，不能当成受访者自己的生活经历。保留研究任务，按对象区分问法；同义主问合并，细节保留为按条件追问。 原编号题：5条；在“原题映射”按本题编号检索。 | H6: 同意
A7: Q-E0-03 | B7: B0 客户/市场/专业证据 核心信息 经销商 媒体 主机厂专家 | C7: 明确参与许可、记录口径与结束核对，执行环节不计研究模块。 | D7: 经销商：还有什么重要情况没有谈到？如果只留下三条建议，您最希望我们记住什么？ 媒体：还有什么重要情况没有谈到？如果只留下三条建议，您最希望我们记住什么？ 主机厂专家：还有什么重要情况没有谈到？如果只留下三条建议，您最希望我们记住什么？ | E7: 1. 核对关键结论是否准确反映受访者意思 2. 区分有证据的观察与有待验证的建议 3. 确认是否有遗漏，不重复全套问题 | F7: 仅对熟悉该业务或有相关证据的经销商、媒体/主机厂专家询问；没有接触或数据可答未知。 原追问1条：在“原追问审阅”按题卡编号筛选；详情保留在该表，不能把全部追问逐项念出。 | G7: 2B渠道/专家提纲：本题回答对象是客户或市场，不能当成受访者自己的生活经历。保留研究任务，按对象区分问法；同义主问合并，细节保留为按条件追问。 原编号题：4条；在“原题映射”按本题编号检索。 | H7: 同意

Sheet 2B-01 受访者与机构背景
A2: 2B-01 受访者与机构背景
A3: 2张题卡。2B：渠道/专家的客户和市场证据。黄色列供你填写；核心信息已回答就不重复问。
A5: 题卡编号 | B5: 子模块与适用方法 | C5: 研究目的与边界 | D5: 主问：按对象选用 | E5: 核心追问：覆盖信息 | F5: 触发条件与观察任务 | G5: 归并调整与来源 | H5: 确认状态 | I5: 你的修改意见
A6: B-CTX-01 | B6: B1 职责与经验 核心信息 经销商 媒体 主机厂专家 | C6: 建立专业受访者及其机构背景，判断后续客户/市场观点的证据边界；这里不问消费者画像。 | D6: 经销商：请介绍您的职责、从业经验，以及目前实际负责的区域、品类或业务。 媒体：请介绍您的职责、从业经验，以及目前实际负责的区域、品类或业务。 主机厂专家：请介绍您的职责、从业经验，以及目前实际负责的区域、品类或业务。 | E6: 1. 受访者职责与直接参与的业务 2. 实际经验年限及近期接触范围 3. 不把本人职位当作对全部市场的了解 | F6: 所有专业受访者；按经销商、媒体、主机厂实际角色展开。 原追问4条：在“原追问审阅”按题卡编号筛选；详情保留在该表，不能把全部追问逐项念出。 | G6: 从原E0背景确认任务拆成职责、机构范围、证据边界三个开场任务；复用来源Q-E0-01。 原编号题：5条；在“原题映射”按本题编号检索。 | H6: 同意
A7: B-CTX-02 | B7: B1 机构与业务范围 核心信息 经销商 媒体 主机厂专家 | C7: 建立专业受访者及其机构背景，判断后续客户/市场观点的证据边界；这里不问消费者画像。 | D7: 经销商：请介绍您所在机构与本次研究相关的业务，以及您能够直接观察的范围。 媒体：请介绍您所在机构与本次研究相关的业务，以及您能够直接观察的范围。 主机厂专家：请介绍您所在机构与本次研究相关的业务，以及您能够直接观察的范围。 | E7: 1. 经销商：门店/集团、代理品牌、业务规模与服务区域 2. 媒体：平台、内容形式、受众和采访/试车范围 3. 主机厂专家：负责市场、产品或工程领域；不要求披露保密信息 | F7: 所有专业受访者；按经销商、媒体、主机厂实际角色展开。 原追问4条：在“原追问审阅”按题卡编号筛选；详情保留在该表，不能把全部追问逐项念出。 | G7: 从原E0背景确认任务拆成职责、机构范围、证据边界三个开场任务；复用来源Q-E0-01。 原编号题：5条；在“原题映射”按本题编号检索。 | H7: 同意

Sheet 2B-02 品牌市场与政策
A2: 2B-02 品牌市场与政策
A3: 4张题卡。2B：渠道/专家的客户和市场证据。黄色列供你填写；核心信息已回答就不重复问。
A5: 题卡编号 | B5: 子模块与适用方法 | C5: 研究目的与边界 | D5: 主问：按对象选用 | E5: 核心追问：覆盖信息 | F5: 触发条件与观察任务 | G5: 归并调整与来源 | H5: 确认状态 | I5: 你的修改意见
A6: B-MKT-01 | B6: B2 竞争格局与品牌表现 核心信息 经销商 媒体 主机厂专家 | C6: 了解目标品类竞争格局、主要品牌及近期变化。 | D6: 经销商：在您负责的区域，目标品类哪些品牌和车型卖得较好？近期有什么变化？ 媒体：从您的报道和观察看，目标品类的主要品牌、车型和竞争变化是什么？ 主机厂专家：在您负责的范围内，目标品类的竞争格局和近期变化是什么？ | E6: 1. 先说明地区、时间和品类口径 2. 区分销量事实、市场观察和个人判断 3. 举一至两个具体品牌或车型例子 | F6: 触发：受访者为经销商，且能够依据近期客户接触、订单、门店记录或售后案例回答。 触发：受访者为媒体，且其报道、试驾、受众调研或公开资料覆盖本议题；不要求回答订单、成交或企业内部数据。 触发：受访者为主机厂专家，且本题属于其市场、产品、工程或渠道职责范围；不要求披露保密信息。 原追问0条：在“原追问审阅”按题卡编号筛选；详情保留在该表，不能把全部追问逐项念出。 | G6: 合并来源题卡：Q-M7.1-01、Q-M7.1-02、Q-M7.1-03。按受访角色与可验证证据重写，减少重复。 原编号题：16条；在“原题映射”按本题编号检索。 | H6: 同意
A7: B-MKT-02 | B7: B2 市场规模与销量预测 核心信息 经销商 媒体 主机厂专家 | C7: 获得有口径的市场规模判断和预测假设。 | D7: 经销商：目标品类近期销量大致怎样？未来一至两年您预计如何变化？ 媒体：公开数据和行业信息显示，目标品类规模和增速怎样？哪些预测较可信？ 主机厂专家：在您负责的范围内，目标品类销量和未来趋势怎样？关键假设是什么？ | E7: 1. 明确数据来源、期间、单位与分母 2. 预测值与实际记录分开 3. 说明最大的不确定因素 | F7: 触发：受访者为经销商，且能够依据近期客户接触、订单、门店记录或售后案例回答。 触发：受访者为媒体，且其报道、试驾、受众调研或公开资料覆盖本议题；不要求回答订单、成交或企业内部数据。 触发：受访者为主机厂专家，且本题属于其市场、产品、工程或渠道职责范围；不要求披露保密信息。 原追问0条：在“原追问审阅”按题卡编号筛选；详情保留在该表，不能把全部追问逐项念出。 | G7: 合并来源题卡：Q-M7.6-01、Q-M7.6-02、Q-M7.6-03。按受访角色与可验证证据重写，减少重复。 原编号题：11条；在“原题映射”按本题编号检索。 | H7: 同意
A8: B-MKT-03 | B8: B2 政策、补贴与税费 核心信息 经销商 媒体 主机厂专家 | C8: 识别当地政策和补贴对需求、价格与动力选择的实际影响。 | D8: 经销商：当地哪些补贴、税费或牌照政策实际影响客户成交？请举订单例子。 媒体：哪些汽车补贴、税费或使用政策最影响市场讨论？依据哪些公开资料？ 主机厂专家：哪些政策影响产品规划或销量？实际影响和预期影响分别是什么？ | E8: 1. 政策名称、有效期和适用车型 2. 对购买时间、预算、动力和车型的影响 3. 政策认知与实际领取分开 | F8: 触发：受访者为经销商，且能够依据近期客户接触、订单、门店记录或售后案例回答。 触发：受访者为媒体，且其报道、试驾、受众调研或公开资料覆盖本议题；不要求回答订单、成交或企业内部数据。 触发：受访者为主机厂专家，且本题属于其市场、产品、工程或渠道职责范围；不要求披露保密信息。 仅在项目组核验政策名称、适用对象和有效期后提示具体政策。 原追问0条：在“原追问审阅”按题卡编号筛选；详情保留在该表，不能把全部追问逐项念出。 | G8: 合并来源题卡：Q-M8.2-01、Q-M8.2-02。按受访角色与可验证证据重写，减少重复。 原编号题：5条；在“原题映射”按本题编号检索。 | H8: 同意
A9: B-MKT-04 | B9: B2 基础设施与能源环境 按需选择 经销商 媒体 主机厂专家 | C9: 判断补能、道路和能源条件对市场发展的限制。 | D9: 经销商：客户最常提到哪些充电、加油或道路条件问题？ 媒体：公开报道和实地观察中，基础设施与能源条件的主要问题是什么？ 主机厂专家：哪些基础设施与能源条件限制了产品或市场发展？ | E9: 1. 说明地区与实际案例 2. 区分城市核心区和其他区域 3. 不按国家标签推定基础设施水平 | F9: 触发：受访者为经销商，且能够依据近期客户接触、订单、门店记录或售后案例回答。 触发：受访者为媒体，且其报道、试驾、受众调研或公开资料覆盖本议题；不要求回答订单、成交或企业内部数据。 触发：受访者为主机厂专家，且本题属于其市场、产品、工程或渠道职责范围；不要求披露保密信息。 原追问0条：在“原追问审阅”按题卡编号筛选；详情保留在该表，不能把全部追问逐项念出。 | G9: 合并来源题卡：Q-M8.1-01、Q-M8.1-02。按受访角色与可验证证据重写，减少重复。 原编号题：3条；在“原题映射”按本题编号检索。 | H9: 同意

Sheet 2B-03 客户画像与用途
A2: 2B-03 客户画像与用途
A3: 4张题卡。2B：渠道/专家的客户和市场证据。黄色列供你填写；核心信息已回答就不重复问。
A5: 题卡编号 | B5: 子模块与适用方法 | C5: 研究目的与边界 | D5: 主问：按对象选用 | E5: 核心追问：覆盖信息 | F5: 触发条件与观察任务 | G5: 归并调整与来源 | H5: 确认状态 | I5: 你的修改意见
A6: B-CUST-01 | B6: B3 核心客户画像 核心信息 经销商 媒体 主机厂专家 | C6: 建立购买目标车型客户的基本画像。 | D6: 经销商：您接触到的目标车型客户通常是什么年龄、职业和家庭阶段？为什么购买？ 媒体：如果您做过受众或用户研究，目标车型人群有哪些稳定特征？ 主机厂专家：现有研究中目标车型用户的核心特征是什么？ | E6: 1. 年龄、职业、家庭阶段与收入只记录可支持的信息 2. 客户原话、样本研究和推断分开 3. 避免用少数个案推断全国 | F6: 触发：受访者为经销商，且能够依据近期客户接触、订单、门店记录或售后案例回答。 触发：受访者为媒体，且其报道、试驾、受众调研或公开资料覆盖本议题；不要求回答订单、成交或企业内部数据。 触发：受访者为主机厂专家，且本题属于其市场、产品、工程或渠道职责范围；不要求披露保密信息。 原追问0条：在“原追问审阅”按题卡编号筛选；详情保留在该表，不能把全部追问逐项念出。 | G6: 合并来源题卡：Q-M1.1-01、Q-M1.1-02、Q-M1.1-04、Q-M1.1-05、Q-M7.2-01。按受访角色与可验证证据重写，减少重复。 原编号题：21条；在“原题映射”按本题编号检索。 | H6: 需修改 | I6: 主机厂的问法很奇怪
A7: B-CUST-02 | B7: B3 购车类型与车辆关系 按需选择 经销商 主机厂专家 | C7: 了解首购、增购、换购及家庭车辆分工。 | D7: 经销商：客户通常是首购、增购还是换购？增购或换购的主要理由是什么？ 主机厂专家：研究中客户通常是首购、增购还是换购？主要驱动分别是什么？ | E7: 1. 现有车辆及使用年限 2. 增购后的车辆分工 3. 换购的触发原因 | F7: 触发：受访者为经销商，且能够依据近期客户接触、订单、门店记录或售后案例回答。 触发：受访者为主机厂专家，且本题属于其市场、产品、工程或渠道职责范围；不要求披露保密信息。 原追问0条：在“原追问审阅”按题卡编号筛选；详情保留在该表，不能把全部追问逐项念出。 | G7: 合并来源题卡：Q-M1.2-01、Q-M1.2-02、Q-M1.2-03。按受访角色与可验证证据重写，减少重复。 原编号题：9条；在“原题映射”按本题编号检索。 | H7: 同意
A8: B-CUST-03 | B8: B3 驾驶者、乘员与决策者 按需选择 经销商 主机厂专家 | C8: 识别车辆使用角色和购买决策链。 | D8: 经销商：目标车型通常由谁开、谁乘坐、谁出钱、谁最终决定？ 主机厂专家：目标用户的驾驶、乘坐和购车决策角色通常如何分工？ | E8: 1. 驾驶者与付款者是否同一人 2. 家庭或组织中影响决策的人 3. 主要乘员和座位安排 | F8: 触发：受访者为经销商，且能够依据近期客户接触、订单、门店记录或售后案例回答。 触发：受访者为主机厂专家，且本题属于其市场、产品、工程或渠道职责范围；不要求披露保密信息。 原追问0条：在“原追问审阅”按题卡编号筛选；详情保留在该表，不能把全部追问逐项念出。 | G8: 合并来源题卡：Q-M1.3-01、Q-M1.3-02、Q-M1.3-03、Q-M1.3-04。按受访角色与可验证证据重写，减少重复。 原编号题：24条；在“原题映射”按本题编号检索。 | H8: 同意
